Workbook

Sheet PRIOVOT
A2: PRIOVOT VCV Sáng | D2: PRIOVOT VCV Chiều | G2: PRIOVOT Dầu Giây Sáng
A3: Row Labels | B3: Sum of Total meals per day | D3: Row Labels | E3: Sum of Total meals per day | G3: Row Labels | H3: Sum of Total meals per day
A4: COO - Assistant | B4: 23 | D4: COO - Maintenance | E4: 51 | G4: COO - Maintenance | H4: 13
A5: COO - Exim | B5: 23 | D5: COO - WWT | E5: 3 | G5: HHVCV | H5: 131
A6: COO - IT | B6: 39 | D6: PMC - Quality | E6: 124 | G6: PMC - Quality | H6: 12
A7: COO - Maintenance | B7: 70 | D7: PMC - WH | E7: 103 | G7: PMC - WH | H7: 72
A8: COO - Purchasing | B8: 71 | D8: Pro - Aging | E8: 768 | G8: Subcontractor | H8: 19
A9: COO - WWT | B9: 23 | D9: Pro - Auto Polishing | E9: 44 | G9: (blank) | H9: 0
A10: COO Assistant | B10: 24 | D10: Pro - CNC | E10: 341 | G10: Pro - Expat | H10: 107
A11: COO Office | B11: 112 | D11: Pro - Data | E11: 84 | G11: Pro - Aging | H11: 2
A12: Finance - Accounting | B12: 148 | D12: Pro - Fabrication | E12: 167 | G12: Pro - Painting | H12: 1
A13: HR Admin | B13: 92 | D13: Pro - Gold Applying | E13: 13 | G13: Pro - Packaging | H13: 52
A14: PMC - Plan | B14: 46 | D14: Pro - Manual Lathe | E14: 29 | G14: Pro - Polishing | H14: 8
A15: PMC - Quality | B15: 487 | D15: Pro - Manual Polishing | E15: 13 | G15: Pro - CNC | H15: 11
... A17: PMC Staff | B17: 48 | D17: Pro - Painting | E17: 152 | G17: Grand Total | H17: 430
A18: Pro - Aging | B18: 1828 | D18: Pro - Polishing | E18: 169
A19: Pro - Auto Polishing | B19: 69 | D19: Pro - Welding | E19: 99
A20: Pro - CNC | B20: 216 | D20: Production | E20: 6
A21: Pro - Data | B21: 398 | D21: SubContractor | E21: 47
A22: Pro - Expat | B22: 619 | D22: (blank) | E22: 0
A23: Pro - Fabrication | B23: 324 | D23: Grand Total | E23: 3469
A24: Pro - Gold Applying | B24: 607 | G24: PRIOVOT Dầu Giây Chiều
A25: Pro - Manual Lathe | B25: 70 | G25: Row Labels | H25: Sum of Total meals per day
A26: Pro - Packaging | B26: 2012 | G26: COO - Maintenance | H26: 0
A27: Pro - Painting | B27: 353 | G27: HHVCV | H27: 55
A28: Pro - Polishing | B28: 269 | G28: PMC - Quality | H28: 0
A29: Pro - Welding | B29: 176 | G29: PMC - WH | H29: 8
A30: Production | B30: 14 | G30: Pro - Expat | H30: 67
A31: Purchase Staff | B31: 24 | G31: Subcontractor | H31: 2
A32: Subcontractor | B32: 176 | G32: (blank) | H32: 0
A33: (blank) | B33: 0 | G33: Grand Total | H33: 132
A34: Grand Total | B34: 8812
A39: Grand Total | B39: =GETPIVOTDATA("Total meals per day",$A$3)+GETPIVOTDATA("Total meals per day",$D$3)+GETPIVOTDATA("Total meals per day",$G$25)+GETPIVOTDATA("Total meals per day",$G$3) -> 12843
B40: =GETPIVOTDATA("Total meals per day",$A$3,"Department","Pro - Expat")+GETPIVOTDATA("Total meals per day",$G$3,"Department","Pro - Expat")+GETPIVOTDATA("Total meals per day",$G$25,"Department","Pro - Expat") -> 793

Sheet VP SÁNG 
I1: 46266 | J1: 46267 | K1: 46268 | L1: 46269 | M1: 46270 | N1: 46271 | O1: 46272 | P1: 46273 | Q1: 46274 | R1: 46275 | S1: 46276 | T1: 46277 | U1: 46278 | V1: 46279 | W1: 46280 | X1: 46281 | Y1: 46282 | Z1: 46283 | AA1: 46284 | AB1: 46285 | AC1: 46286 | AD1: 46287 | AE1: 46288 | AF1: 46289 | AG1: 46290 | AH1: 46291 | AI1: 46292 | AJ1: 46293 | AK1: 46294 | AL1: 46295
G2: Shift 1 + normal shift | H2: Ca sáng | I2: =SUM(I3:I7) -> 361 | J2: =SUM(J3:J7) -> 0 | K2: =SUM(K3:K7) -> 0 | L2: =SUM(L3:L7) -> 358 | M2: =SUM(M3:M7) -> 363 | N2: =SUM(N3:N7) -> 72 | O2: =SUM(O3:O7) -> 370 | P2: =SUM(P3:P7) -> 329 | ... AL2: =SUM(AL3:AL7) -> 364
G3: DS- CN food | H3: Sáng - Trung | I3: =COUNTIFS(I$13:I$663,$H3) -> 25 | J3: =COUNTIFS(J$13:J$663,$H3) -> 0 | K3: =COUNTIFS(K$13:K$663,$H3) -> 0 | L3: =COUNTIFS(L$13:L$663,$H3) -> 25 | M3: =COUNTIFS(M$13:M$663,$H3) -> 24 | N3: =COUNTIFS(N$13:N$663,$H3) -> 5 | O3: =COUNTIFS(O$13:O$663,$H3) -> 25 | P3: =COUNTIFS(P$13:P$663,$H3) -> 25 | ... AL3: =COUNTIFS(AL$13:AL$663,$H3) -> 25
D4: backup | E4: 1 | G4: DS- VN food - Office | H4: Sáng - Mặn - VP | I4: =COUNTIFS(I$13:I$663,$H4) -> 28 | J4: =COUNTIFS(J$13:J$663,$H4) -> 0 | K4: =COUNTIFS(K$13:K$663,$H4) -> 0 | L4: =COUNTIFS(L$13:L$663,$H4) -> 29 | M4: =COUNTIFS(M$13:M$663,$H4) -> 29 | N4: =COUNTIFS(N$13:N$663,$H4) -> 0 | O4: =COUNTIFS(O$13:O$663,$H4) -> 32 | P4: =COUNTIFS(P$13:P$663,$H4) -> 30 | ... AL4: =COUNTIFS(AL$13:AL$663,$H4) -> 29
G5: DS- Vegetarian rice - Office | H5: Sáng - Chay - VP | I5: =COUNTIFS(I$13:I$663,$H5) -> 2 | J5: =COUNTIFS(J$13:J$663,$H5) -> 0 | K5: =COUNTIFS(K$13:K$663,$H5) -> 0 | L5: =COUNTIFS(L$13:L$663,$H5) -> 6 | M5: =COUNTIFS(M$13:M$663,$H5) -> 4 | N5: =COUNTIFS(N$13:N$663,$H5) -> 0 | O5: =COUNTIFS(O$13:O$663,$H5) -> 4 | P5: =COUNTIFS(P$13:P$663,$H5) -> 4 | ... AL5: =COUNTIFS(AL$13:AL$663,$H5) -> 5
G6: DS- VN food | H6: Sáng - Mặn - Xưởng | I6: =COUNTIFS(I$13:I$663,$H6)-I7 -> 253 | J6: =COUNTIFS(J$13:J$663,$H6)-J7 -> 0 | K6: =COUNTIFS(K$13:K$663,$H6)-K7 -> 0 | L6: =COUNTIFS(L$13:L$663,$H6)-L7 -> 254 | M6: =COUNTIFS(M$13:M$663,$H6)-M7 -> 263 | N6: =COUNTIFS(N$13:N$663,$H6)-N7 -> 67 | O6: =COUNTIFS(O$13:O$663,$H6)-O7 -> 269 | P6: =COUNTIFS(P$13:P$663,$H6)-P7 -> 238 | ... AL6: =COUNTIFS(AL$13:AL$663,$H6)-AL7 -> 268
G7: DS- Vegetarian rice | H7: Sáng - Chay - Xưởng | I7: =3+1+37+12 -> 53 | L7: =1+3+28+12 -> 44 | M7: =1+12+28+2 -> 43 | O7: =10+27+1+2 -> 40 | P7: 32 | Q7: =3+13+1+12 -> 29 | R7: =14+2+14+1 -> 31 | S7: =2+1+22+13 -> 38 | T7: =12+1 -> 13 | V7: =2+10+26+1 -> 39 | W7: =23+2+10+1 -> 36 | X7: =1+10+2+25 -> 38 | Y7: =39 -> 39 | Z7: =2+24+1+13 -> 40 | AA7: =35+12+1+2 -> 50 | AB7: =10 -> 10 | AC7: =1+11+2+24 -> 38 | AD7: =1+12+2+24 -> 39 | AE7: =11+2+23+1 -> 37 | AF7: =1+24+2+12 -> 39 | AG7: =12+1+26+2 -> 41 | AH7: =10+1+2+25 -> 38 | AI7: =8 -> 8 | AJ7: =2+11+23 -> 36 | AK7: =11+1+1+24 -> 37 | AL7: =25+1+1+10 -> 37
E8: =SUM(I8:AL8) -> 8812 | I8: =SUM(I9:I10) -> 361 | J8: =SUM(J9:J10) -> 0 | K8: =SUM(K9:K10) -> 0 | L8: =SUM(L9:L10) -> 358 | M8: =SUM(M9:M10) -> 363 | N8: =SUM(N9:N10) -> 72 | O8: =SUM(O9:O10) -> 370 | P8: =SUM(P9:P10) -> 329 | ... AL8: =SUM(AL9:AL10) -> 364
E9: =SUM(I9:AL9) -> 619 | G9: Total Expat Meals | I9: =I3 -> 25 | J9: =J3 -> 0 | K9: =K3 -> 0 | L9: =L3 -> 25 | M9: =M3 -> 24 | N9: =N3 -> 5 | O9: =O3 -> 25 | P9: =P3 -> 25 | ... AL9: =AL3 -> 25
E10: =SUM(I10:AL10) -> 8193 | G10: Total Vietnamese Meals | I10: =I2-I3 -> 336 | J10: =J2-J3 -> 0 | K10: =K2-K3 -> 0 | L10: =L2-L3 -> 333 | M10: =M2-M3 -> 339 | N10: =N2-N3 -> 67 | O10: =O2-O3 -> 345 | P10: =P2-P3 -> 304 | ... AL10: =AL2-AL3 -> 339
AM12: =E8-SUM(AM14:AM353) -> 1825
A13: Status | B13: Code | C13: Fullname VN | D13: Department | E13: Section | F13: Place | H13: Last day | AM13: Total meals per day
A14: Active | B14: HOLA001 | C14: Trần Thị Thúy Phượng | D14: Subcontractor | E14: Subcontractor | F14: Factory | I14: Sáng - Mặn - Xưởng | L14: Sáng - Mặn - Xưởng | M14: Sáng - Mặn - Xưởng | O14: Sáng - Mặn - Xưởng | P14: Sáng - Mặn - Xưởng | Q14: Sáng - Mặn - Xưởng | R14: Sáng - Mặn - Xưởng | S14: Sáng - Mặn - Xưởng | T14: Sáng - Mặn - Xưởng | V14: Sáng - Mặn - Xưởng | W14: Sáng - Mặn - Xưởng | X14: Sáng - Mặn - Xưởng | Y14: Sáng - Mặn - Xưởng | Z14: Sáng - Mặn - Xưởng | AA14: Sáng - Mặn - Xưởng | AC14: Sáng - Mặn - Xưởng | AD14: Sáng - Mặn - Xưởng | AE14: Sáng - Mặn - Xưởng | AF14: Sáng - Mặn - Xưởng | AG14: Sáng - Mặn - Xưởng | AH14: Sáng - Mặn - Xưởng | AJ14: Sáng - Mặn - Xưởng | AK14: Sáng - Mặn - Xưởng | AL14: Sáng - Mặn - Xưởng | AM14: =COUNTA(I14:AL14)-COUNTIF(I14:AL14,"CT") -> 24
A15: Active | B15: HOLA003 | C15: Trần Thị Lệ Sáng | D15: Subcontractor | E15: Subcontractor | F15: Factory | I15: Sáng - Mặn - Xưởng | L15: Sáng - Mặn - Xưởng | M15: Sáng - Mặn - Xưởng | O15: Sáng - Mặn - Xưởng | P15: Sáng - Mặn - Xưởng | Q15: Sáng - Mặn - Xưởng | R15: Sáng - Mặn - Xưởng | S15: Sáng - Mặn - Xưởng | T15: Sáng - Mặn - Xưởng | V15: Sáng - Mặn - Xưởng | W15: Sáng - Mặn - Xưởng | X15: Sáng - Mặn - Xưởng | Y15: Sáng - Mặn - Xưởng | Z15: Sáng - Mặn - Xưởng | AA15: Sáng - Mặn - Xưởng | AC15: Sáng - Mặn - Xưởng | AD15: Sáng - Mặn - Xưởng | AE15: Sáng - Mặn - Xưởng | AF15: Sáng - Mặn - Xưởng | AG15: Sáng - Mặn - Xưởng | AH15: Sáng - Mặn - Xưởng | AK15: Sáng - Mặn - Xưởng | AL15: Sáng - Mặn - Xưởng | AM15: =COUNTA(I15:AL15)-COUNTIF(I15:AL15,"CT") -> 23
A16: Active | B16: HOLA004 | C16: Nguyễn Thị Chỉnh | D16: Subcontractor | E16: Subcontractor | F16: Office | G16: Chay | L16: Sáng - Chay - VP | M16: Sáng - Chay - VP | O16: Sáng - Chay - VP | P16: Sáng - Chay - VP | Q16: Sáng - Chay - VP | R16: Sáng - Chay - VP | S16: Sáng - Chay - VP | T16: Sáng - Chay - VP | V16: Sáng - Chay - VP | W16: Sáng - Chay - VP | X16: Sáng - Chay - VP | Y16: Sáng - Chay - VP | Z16: Sáng - Chay - VP | AA16: Sáng - Chay - VP | AC16: Sáng - Chay - VP | AD16: Sáng - Chay - VP | AE16: Sáng - Chay - VP | AF16: Sáng - Chay - VP | AG16: Sáng - Chay - VP | AH16: Sáng - Chay - VP | AJ16: Sáng - Chay - VP | AK16: Sáng - Chay - VP | AL16: Sáng - Chay - VP | AM16: =COUNTA(I16:AL16)-COUNTIF(I16:AL16,"CT") -> 23
A17: Active | B17: HOLA005 | C17: Nguyễn Thị Chín | D17: Subcontractor | E17: Subcontractor | F17: Factory | I17: Sáng - Mặn - Xưởng | L17: Sáng - Mặn - Xưởng | M17: Sáng - Mặn - Xưởng | O17: Sáng - Mặn - Xưởng | P17: Sáng - Mặn - Xưởng | Q17: Sáng - Mặn - Xưởng | R17: Sáng - Mặn - Xưởng | S17: Sáng - Mặn - Xưởng | T17: Sáng - Mặn - Xưởng | V17: Sáng - Mặn - Xưởng | W17: Sáng - Mặn - Xưởng | X17: Sáng - Mặn - Xưởng | Y17: Sáng - Mặn - Xưởng | Z17: Sáng - Mặn - Xưởng | AA17: Sáng - Mặn - Xưởng | AC17: Sáng - Mặn - Xưởng | AD17: Sáng - Mặn - Xưởng | AE17: Sáng - Mặn - Xưởng | AF17: Sáng - Mặn - Xưởng | AG17: Sáng - Mặn - Xưởng | AH17: Sáng - Mặn - Xưởng | AJ17: Sáng - Mặn - Xưởng | AK17: Sáng - Mặn - Xưởng | AL17: Sáng - Mặn - Xưởng | AM17: =COUNTA(I17:AL17)-COUNTIF(I17:AL17,"CT") -> 24
A18: Active | B18: PTT0451 | C18: Trần Huy Cường | D18: Pro - Packaging | E18: Pro - Packaging | F18: Factory | I18: Sáng - Mặn - Xưởng | M18: Sáng - Mặn - Xưởng | AM18: =COUNTA(I18:AL18)-COUNTIF(I18:AL18,"CT") -> 2
A19: Active | B19: PTT0583 | C19: Võ Thị Ánh Nguyệt | D19: Pro - Aging | E19: Pro - Aging | F19: Factory | I19: Sáng - Mặn - Xưởng | M19: Sáng - Mặn - Xưởng | N19: Sáng - Mặn - Xưởng | AM19: =COUNTA(I19:AL19)-COUNTIF(I19:AL19,"CT") -> 3
A20: Active | B20: PTT0591 | C20: Nguyễn Thị Thủy | D20: Pro - Aging | E20: Pro - Aging | F20: Factory | I20: Sáng - Mặn - Xưởng | AM20: =COUNTA(I20:AL20)-COUNTIF(I20:AL20,"CT") -> 1
A21: Active | B21: PTT0592 | C21: Nguyễn Thị Hương | D21: Pro - Aging | E21: Pro - Aging | F21: Factory | I21: Sáng - Mặn - Xưởng | L21: Sáng - Mặn - Xưởng | M21: Sáng - Mặn - Xưởng | AM21: =COUNTA(I21:AL21)-COUNTIF(I21:AL21,"CT") -> 3
A22: Active | B22: PTT0593 | C22: Nguyễn Thị Thanh Huyền | D22: Pro - Aging | E22: Pro - Aging | F22: Factory | I22: Sáng - Mặn - Xưởng | L22: Sáng - Mặn - Xưởng | AM22: =COUNTA(I22:AL22)-COUNTIF(I22:AL22,"CT") -> 2
A23: Active | B23: PTT0598 | C23: Nguyễn Hải Yến | D23: Pro - Packaging | E23: Pro - Packaging | F23: Factory | I23: Sáng - Mặn - Xưởng | M23: Sáng - Mặn - Xưởng | N23: Sáng - Mặn - Xưởng | AM23: =COUNTA(I23:AL23)-COUNTIF(I23:AL23,"CT") -> 3
A24: Active | B24: PTT0599 | C24: Trịnh Thị Nương Em | D24: Pro - Packaging | E24: Pro - Packaging | F24: Factory | I24: Sáng - Mặn - Xưởng | AM24: =COUNTA(I24:AL24)-COUNTIF(I24:AL24,"CT") -> 1
A25: Active | B25: PTT0615 | C25: Nguyễn Văn Phước | D25: Pro - Packaging | E25: Pro - Packaging | F25: Factory | I25: Sáng - Mặn - Xưởng | M25: Sáng - Mặn - Xưởng | N25: Sáng - Mặn - Xưởng | AM25: =COUNTA(I25:AL25)-COUNTIF(I25:AL25,"CT") -> 3
A26: Active | B26: VCV0797 | C26: Từ Tuấn Tú | D26: Pro - Packaging | E26: Pro - Packaging | F26: Factory | I26: Sáng - Mặn - Xưởng | L26: Sáng - Mặn - Xưởng | M26: Sáng - Mặn - Xưởng | N26: Sáng - Mặn - Xưởng | O26: Sáng - Mặn - Xưởng | P26: Sáng - Mặn - Xưởng | Q26: Sáng - Mặn - Xưởng | R26: Sáng - Mặn - Xưởng | S26: Sáng - Mặn - Xưởng | T26: Sáng - Mặn - Xưởng | V26: Sáng - Mặn - Xưởng | W26: Sáng - Mặn - Xưởng | X26: Sáng - Mặn - Xưởng | Y26: Sáng - Mặn - Xưởng | Z26: Sáng - Mặn - Xưởng | AA26: Sáng - Mặn - Xưởng | AB26: Sáng - Mặn - Xưởng | AC26: Sáng - Mặn - Xưởng | AD26: Sáng - Mặn - Xưởng | AE26: Sáng - Mặn - Xưởng | AG26: Sáng - Mặn - Xưởng | AH26: Sáng - Mặn - Xưởng | AJ26: Sáng - Mặn - Xưởng | AK26: Sáng - Mặn - Xưởng | AL26: Sáng - Mặn - Xưởng | AM26: =COUNTA(I26:AL26)-COUNTIF(I26:AL26,"CT") -> 25
A27: Active | B27: VCV0796 | C27: Lý Văn Luôl | D27: Pro - Packaging | E27: Pro - Packaging | F27: Factory | I27: Sáng - Mặn - Xưởng | L27: Sáng - Mặn - Xưởng | M27: Sáng - Mặn - Xưởng | N27: Sáng - Mặn - Xưởng | O27: Sáng - Mặn - Xưởng | P27: Sáng - Mặn - Xưởng | Q27: Sáng - Mặn - Xưởng | R27: Sáng - Mặn - Xưởng | S27: Sáng - Mặn - Xưởng | T27: Sáng - Mặn - Xưởng | V27: Sáng - Mặn - Xưởng | W27: Sáng - Mặn - Xưởng | X27: Sáng - Mặn - Xưởng | Y27: Sáng - Mặn - Xưởng | Z27: Sáng - Mặn - Xưởng | AA27: Sáng - Mặn - Xưởng | AB27: Sáng - Mặn - Xưởng | AC27: Sáng - Mặn - Xưởng | AD27: Sáng - Mặn - Xưởng | AE27: Sáng - Mặn - Xưởng | AF27: Sáng - Mặn - Xưởng | AG27: Sáng - Mặn - Xưởng | AH27: Sáng - Mặn - Xưởng | AJ27: Sáng - Mặn - Xưởng | AK27: Sáng - Mặn - Xưởng | AL27: Sáng - Mặn - Xưởng | AM27: =COUNTA(I27:AL27)-COUNTIF(I27:AL27,"CT") -> 26
A28: Active | B28: VCV0794 | C28: Khưu Thị Cẩm Lai | D28: Pro - Packaging | E28: Pro - Packaging | F28: Factory | I28: Sáng - Mặn - Xưởng | L28: Sáng - Mặn - Xưởng | M28: Sáng - Mặn - Xưởng | N28: Sáng - Mặn - Xưởng | O28: Sáng - Mặn - Xưởng | P28: Sáng - Mặn - Xưởng | Q28: Sáng - Mặn - Xưởng | R28: Sáng - Mặn - Xưởng | T28: Sáng - Mặn - Xưởng | V28: Sáng - Mặn - Xưởng | W28: Sáng - Mặn - Xưởng | X28: Sáng - Mặn - Xưởng | Y28: Sáng - Mặn - Xưởng | Z28: Sáng - Mặn - Xưởng | AA28: Sáng - Mặn - Xưởng | AC28: Sáng - Mặn - Xưởng | AD28: Sáng - Mặn - Xưởng | AE28: Sáng - Mặn - Xưởng | AF28: Sáng - Mặn - Xưởng | AG28: Sáng - Mặn - Xưởng | AH28: Sáng - Mặn - Xưởng | AI28: Sáng - Mặn - Xưởng | AJ28: Sáng - Mặn - Xưởng | AK28: Sáng - Mặn - Xưởng | AL28: Sáng - Mặn - Xưởng | AM28: =COUNTA(I28:AL28)-COUNTIF(I28:AL28,"CT") -> 25
A29: Active | B29: PTT0636 | C29: Hà Thị Thanh | D29: Pro - Aging | E29: Pro - Aging | F29: Factory | I29: Sáng - Mặn - Xưởng | L29: Sáng - Mặn - Xưởng | M29: Sáng - Mặn - Xưởng | AM29: =COUNTA(I29:AL29)-COUNTIF(I29:AL29,"CT") -> 3
A30: Active | B30: PTT0637 | C30: Đào Thị Kim Oanh | D30: Pro - Aging | E30: Pro - Aging | F30: Factory | I30: Sáng - Mặn - Xưởng | L30: Sáng - Mặn - Xưởng | M30: Sáng - Mặn - Xưởng | AM30: =COUNTA(I30:AL30)-COUNTIF(I30:AL30,"CT") -> 3
A31: Active | B31: VCV0795 | C31: Trần Thị Quỳnh Như | D31: Pro - Packaging | E31: Pro - Packaging | F31: Factory | I31: Sáng - Mặn - Xưởng | L31: Sáng - Mặn - Xưởng | M31: Sáng - Mặn - Xưởng | O31: Sáng - Mặn - Xưởng | P31: Sáng - Mặn - Xưởng | Q31: Sáng - Mặn - Xưởng | R31: Sáng - Mặn - Xưởng | S31: Sáng - Mặn - Xưởng | T31: Sáng - Mặn - Xưởng | V31: Sáng - Mặn - Xưởng | W31: Sáng - Mặn - Xưởng | X31: Sáng - Mặn - Xưởng | Y31: Sáng - Mặn - Xưởng | Z31: Sáng - Mặn - Xưởng | AA31: Sáng - Mặn - Xưởng | AC31: Sáng - Mặn - Xưởng | AD31: Sáng - Mặn - Xưởng | AE31: Sáng - Mặn - Xưởng | AF31: Sáng - Mặn - Xưởng | AG31: Sáng - Mặn - Xưởng | AH31: Sáng - Mặn - Xưởng | AI31: Sáng - Mặn - Xưởng | AJ31: Sáng - Mặn - Xưởng | AK31: Sáng - Mặn - Xưởng | AL31: Sáng - Mặn - Xưởng | AM31: =COUNTA(I31:AL31)-COUNTIF(I31:AL31,"CT") -> 25
A32: Active | B32: VCV0793 | C32: Võ Thị Kim Chung | D32: Pro - Packaging | E32: Pro - Packaging | F32: Factory | I32: Sáng - Mặn - Xưởng | L32: Sáng - Mặn - Xưởng | M32: Sáng - Mặn - Xưởng | N32: Sáng - Mặn - Xưởng | O32: Sáng - Mặn - Xưởng | P32: Sáng - Mặn - Xưởng | Q32: Sáng - Mặn - Xưởng | R32: Sáng - Mặn - Xưởng | AM32: =COUNTA(I32:AL32)-COUNTIF(I32:AL32,"CT") -> 8
A33: Active | B33: TNBH0020 | C33: Lê Tuyết Anh | D33: Pro - Packaging | E33: Pro - Packaging | F33: Factory | I33: Sáng - Mặn - Xưởng | M33: Sáng - Mặn - Xưởng | N33: Sáng - Mặn - Xưởng | AM33: =COUNTA(I33:AL33)-COUNTIF(I33:AL33,"CT") -> 3
A34: Active | B34: VCV0002 | C34: Dương Thị Vy Thảo | D34: HR Admin | E34: HR Admin | F34: Factory | I34: Sáng - Mặn - Xưởng | L34: Sáng - Mặn - Xưởng | M34: Sáng - Mặn - Xưởng | O34: Sáng - Mặn - Xưởng | P34: Sáng - Mặn - Xưởng | Q34: Sáng - Mặn - Xưởng | R34: Sáng - Mặn - Xưởng | S34: Sáng - Mặn - Xưởng | T34: Sáng - Mặn - Xưởng | V34: Sáng - Mặn - Xưởng | W34: Sáng - Mặn - Xưởng | X34: Sáng - Mặn - Xưởng | Y34: Sáng - Mặn - Xưởng | Z34: Sáng - Mặn - Xưởng | AA34: Sáng - Mặn - Xưởng | AC34: Sáng - Mặn - Xưởng | AD34: Sáng - Mặn - Xưởng | AE34: Sáng - Mặn - Xưởng | AF34: Sáng - Mặn - Xưởng | AG34: Sáng - Mặn - Xưởng | AH34: Sáng - Mặn - Xưởng | AJ34: Sáng - Mặn - Xưởng | AK34: Sáng - Mặn - Xưởng | AL34: Sáng - Mặn - Xưởng | AM34: =COUNTA(I34:AL34)-COUNTIF(I34:AL34,"CT") -> 24
A35: Active | B35: VCV0752 | C35: Dương Anh Thư | D35: HR Admin | E35: HR Admin | F35: Office | I35: Sáng - Mặn - VP | L35: Sáng - Mặn - VP | M35: Sáng - Mặn - VP | O35: Sáng - Mặn - VP | Q35: Sáng - Mặn - VP | R35: Sáng - Mặn - VP | S35: Sáng - Mặn - VP | T35: Sáng - Mặn - VP | V35: Sáng - Mặn - VP | W35: Sáng - Mặn - VP | X35: Sáng - Mặn - VP | Y35: Sáng - Mặn - VP | Z35: Sáng - Mặn - VP | AA35: Sáng - Mặn - VP | AC35: Sáng - Mặn - VP | AD35: Sáng - Mặn - VP | AE35: Sáng - Mặn - VP | AF35: Sáng - Mặn - VP | AG35: Sáng - Mặn - VP | AH35: Sáng - Mặn - VP | AJ35: Sáng - Mặn - VP | AK35: Sáng - Mặn - VP | AL35: Sáng - Mặn - VP | AM35: =COUNTA(I35:AL35)-COUNTIF(I35:AL35,"CT") -> 23
A36: Active | B36: VCV0004 | C36: Trần Thu Thủy | D36: PMC - Quality | E36: PMC - Quality | F36: Factory | O36: Sáng - Mặn - VP | Q36: Sáng - Mặn - VP | R36: Sáng - Mặn - VP | S36: Sáng - Mặn - VP | T36: Sáng - Mặn - VP | V36: Sáng - Mặn - VP | W36: Sáng - Mặn - VP | X36: Sáng - Mặn - Xưởng | Y36: Sáng - Mặn - Xưởng | Z36: Sáng - Mặn - Xưởng | AA36: Sáng - Mặn - Xưởng | AC36: Sáng - Mặn - Xưởng | AD36: Sáng - Mặn - Xưởng | AE36: Sáng - Mặn - Xưởng | AF36: Sáng - Mặn - Xưởng | AG36: Sáng - Mặn - Xưởng | AH36: Sáng - Mặn - Xưởng | AJ36: Sáng - Mặn - Xưởng | AK36: Sáng - Mặn - Xưởng | AL36: CT | AM36: =COUNTA(I36:AL36)-COUNTIF(I36:AL36,"CT") -> 19
A37: Active | B37: VCV0007 | C37: Hoàng Thị Thanh Xuân | D37: COO - Assistant | E37: COO Office | F37: Office | I37: Sáng - Mặn - VP | L37: Sáng - Mặn - VP | M37: Sáng - Mặn - VP | O37: Sáng - Mặn - VP | P37: Sáng - Mặn - VP | R37: Sáng - Mặn - VP | S37: Sáng - Mặn - VP | T37: Sáng - Mặn - VP | V37: Sáng - Mặn - VP | W37: Sáng - Mặn - VP | X37: Sáng - Mặn - VP | Y37: Sáng - Mặn - VP | Z37: Sáng - Mặn - VP | AA37: Sáng - Mặn - VP | AC37: Sáng - Mặn - VP | AD37: Sáng - Mặn - VP | AE37: Sáng - Mặn - VP | AF37: Sáng - Mặn - VP | AG37: Sáng - Mặn - VP | AH37: Sáng - Mặn - VP | AJ37: Sáng - Mặn - VP | AK37: Sáng - Mặn - VP | AL37: Sáng - Mặn - VP | AM37: =COUNTA(I37:AL37)-COUNTIF(I37:AL37,"CT") -> 23
A38: Active | B38: VCV0009 | C38: Nguyễn Hoàng Khang | D38: COO - Maintenance | E38: COO Office | F38: Factory | I38: Sáng - Mặn - Xưởng | L38: Sáng - Mặn - Xưởng | M38: Sáng - Mặn - Xưởng | O38: Sáng - Mặn - Xưởng | P38: Sáng - Mặn - Xưởng | Q38: Sáng - Mặn - Xưởng | R38: Sáng - Mặn - Xưởng | S38: Sáng - Mặn - Xưởng | T38: Sáng - Mặn - Xưởng | V38: Sáng - Mặn - Xưởng | W38: Sáng - Mặn - Xưởng | X38: Sáng - Mặn - Xưởng | Y38: Sáng - Mặn - Xưởng | Z38: Sáng - Mặn - Xưởng | AA38: Sáng - Mặn - Xưởng | AC38: Sáng - Mặn - Xưởng | AD38: Sáng - Mặn - Xưởng | AF38: Sáng - Mặn - Xưởng | AG38: Sáng - Mặn - Xưởng | AH38: Sáng - Mặn - Xưởng | AJ38: Sáng - Mặn - Xưởng | AK38: Sáng - Mặn - Xưởng | AL38: Sáng - Mặn - Xưởng | AM38: =COUNTA(I38:AL38)-COUNTIF(I38:AL38,"CT") -> 23
A39: Active | B39: VCV0011 | C39: Nguyễn Thị Minh Hiền | D39: COO - Purchasing | E39: COO Office | F39: Factory | I39: Sáng - Mặn - Xưởng | L39: Sáng - Mặn - Xưởng | M39: Sáng - Mặn - Xưởng | O39: Sáng - Mặn - Xưởng | P39: Sáng - Mặn - Xưởng | Q39: Sáng - Mặn - Xưởng | R39: Sáng - Mặn - Xưởng | S39: Sáng - Mặn - Xưởng | T39: Sáng - Mặn - Xưởng | V39: Sáng - Mặn - Xưởng | W39: Sáng - Mặn - Xưởng | X39: Sáng - Mặn - Xưởng | Y39: Sáng - Mặn - Xưởng | Z39: Sáng - Mặn - Xưởng | AA39: Sáng - Mặn - Xưởng | AC39: Sáng - Mặn - Xưởng | AD39: Sáng - Mặn - Xưởng | AE39: Sáng - Mặn - Xưởng | AF39: Sáng - Mặn - Xưởng | AG39: Sáng - Mặn - Xưởng | AH39: Sáng - Mặn - Xưởng | AJ39: Sáng - Mặn - Xưởng | AK39: Sáng - Mặn - Xưởng | AL39: Sáng - Mặn - Xưởng | AM39: =COUNTA(I39:AL39)-COUNTIF(I39:AL39,"CT") -> 24
A40: Active | B40: VCV0012 | C40: Nguyễn Kim Chi | D40: PMC - Plan | E40: PMC - Plan | F40: Office | I40: Sáng - Mặn - VP | L40: Sáng - Mặn - VP | M40: Sáng - Mặn - VP | O40: Sáng - Mặn - VP | P40: Sáng - Mặn - VP | Q40: Sáng - Mặn - VP | R40: Sáng - Mặn - VP | S40: Sáng - Mặn - VP | T40: Sáng - Mặn - VP | V40: Sáng - Mặn - VP | W40: Sáng - Mặn - VP | X40: Sáng - Mặn - VP | Y40: Sáng - Mặn - VP | Z40: Sáng - Mặn - VP | AC40: Sáng - Mặn - VP | AD40: Sáng - Mặn - VP | AE40: Sáng - Mặn - VP | AF40: Sáng - Mặn - VP | AG40: Sáng - Mặn - VP | AH40: Sáng - Mặn - VP | AK40: Sáng - Mặn - VP | AL40: Sáng - Mặn - VP | AM40: =COUNTA(I40:AL40)-COUNTIF(I40:AL40,"CT") -> 22
A41: Active | B41: VCV0015 | C41: Trương Phát Minh | D41: COO - IT | E41: COO Office | F41: Factory | M41: Sáng - Mặn - Xưởng | O41: Sáng - Mặn - Xưởng | P41: Sáng - Mặn - Xưởng | Q41: Sáng - Mặn - Xưởng | R41: Sáng - Mặn - Xưởng | S41: Sáng - Mặn - Xưởng | T41: Sáng - Mặn - Xưởng | W41: Sáng - Mặn - Xưởng | X41: Sáng - Mặn - Xưởng | Y41: Sáng - Mặn - Xưởng | AA41: Sáng - Mặn - Xưởng | AC41: Sáng - Mặn - Xưởng | AD41: Sáng - Mặn - Xưởng | AE41: Sáng - Mặn - Xưởng | AF41: Sáng - Mặn - VP | AG41: Sáng - Mặn - VP | AH41: Sáng - Mặn - Xưởng | AJ41: Sáng - Mặn - VP | AK41: Sáng - Mặn - VP | AL41: Sáng - Mặn - VP | AM41: =COUNTA(I41:AL41)-COUNTIF(I41:AL41,"CT") -> 20
...

Sheet CHIỀU 
I1: 46266 | J1: 46267 | K1: 46268 | L1: 46269 | M1: 46270 | N1: 46271 | O1: 46272 | P1: 46273 | Q1: 46274 | R1: 46275 | S1: 46276 | T1: 46277 | U1: 46278 | V1: 46279 | W1: 46280 | X1: 46281 | Y1: 46282 | Z1: 46283 | AA1: 46284 | AB1: 46285 | AC1: 46286 | AD1: 46287 | AE1: 46288 | AF1: 46289 | AG1: 46290 | AH1: 46291 | AI1: 46292 | AJ1: 46293 | AK1: 46294 | AL1: 46295
J2: =SUM(J3:J7) -> 0 | K2: =SUM(K3:K7) -> 0 | L2: =SUM(L3:L7) -> 0 | N2: =SUM(N3:N7) -> 0 | O2: =SUM(O3:O7) -> 0 | P2: =SUM(P3:P7) -> 0 | Q2: =SUM(Q3:Q7) -> 0 | R2: =SUM(R3:R7) -> 0 | S2: =SUM(S3:S7) -> 0 | T2: =SUM(T3:T7) -> 0 | U2: =SUM(U3:U7) -> 0 | ... AK2: =SUM(AK3:AK7) -> 0
I3: =COUNTIFS(I$15:I$101,$H3) -> 0 | J3: =COUNTIFS(J$15:J$101,$H3) -> 0 | K3: =COUNTIFS(K$15:K$101,$H3) -> 0 | L3: =COUNTIFS(L$15:L$101,$H3) -> 0 | N3: =COUNTIFS(N$15:N$101,$H3) -> 0 | O3: =COUNTIFS(O$15:O$101,$H3) -> 0 | P3: =COUNTIFS(P$15:P$101,$H3) -> 0 | Q3: =COUNTIFS(Q$15:Q$101,$H3) -> 0 | R3: =COUNTIFS(R$15:R$101,$H3) -> 0 | S3: =COUNTIFS(S$15:S$101,$H3) -> 0 | T3: =COUNTIFS(T$15:T$101,$H3) -> 0 | U3: =COUNTIFS(U$15:U$101,$H3) -> 0 | ... AK3: =COUNTIFS(AK$15:AK$101,$H3) -> 0
I4: =COUNTIFS(I$15:I$101,$H4)-I5 -> 0 | J4: =COUNTIFS(J$15:J$101,$H4)-J5 -> 0 | K4: =COUNTIFS(K$15:K$101,$H4)-K5 -> 0 | L4: =COUNTIFS(L$15:L$101,$H4)-L5 -> 0 | N4: =COUNTIFS(N$15:N$101,$H4)-N5 -> 0 | O4: =COUNTIFS(O$15:O$101,$H4)-O5 -> 0 | P4: =COUNTIFS(P$15:P$101,$H4)-P5 -> 0 | Q4: =COUNTIFS(Q$15:Q$101,$H4)-Q5 -> 0 | R4: =COUNTIFS(R$15:R$101,$H4)-R5 -> 0 | S4: =COUNTIFS(S$15:S$101,$H4)-S5 -> 0 | T4: =COUNTIFS(T$15:T$101,$H4)-T5 -> 0 | U4: =COUNTIFS(U$15:U$101,$H4)-U5 -> 0 | ... AK4: =COUNTIFS(AK$15:AK$101,$H4)-AK5 -> 0
G7: DS- Vegetarian rice | H7: Cơm ca đêm
G8: Shift 2 | H8: Ca chiều | I8: =I9+I12 -> 16 | J8: =J9+J12 -> 0 | K8: =K9+K12 -> 0 | L8: =L9+L12 -> 130 | M8: =M9+M12 -> 18 | N8: =N9+N12 -> 0 | O8: =O9+O12 -> 124 | P8: =P9+P12 -> 133 | ... AL8: =AL9+AL12 -> 151
G9: Savory Dinner | H9: Cơm Chiều Mặn | I9: =SUM(I10:I11)-I12 -> 16 | J9: =SUM(J10:J11)-J12 -> 0 | K9: =SUM(K10:K11)-K12 -> 0 | L9: =SUM(L10:L11)-L12 -> 119 | M9: =SUM(M10:M11)-M12 -> 18 | N9: =SUM(N10:N11)-N12 -> 0 | O9: =SUM(O10:O11)-O12 -> 115 | P9: =SUM(P10:P11)-P12 -> 122 | ... AL9: =SUM(AL10:AL11)-AL12 -> 140
B10: giao | C10: Cơm Ca 2 | D10: 10 | F10: =SUM(I10:AK10) -> 171 | G10: Overtime meal | H10: Cơm Ca 2 | I10: =COUNTIFS($I15:I$455,$H$10) -> 3 | J10: =COUNTIFS(J16:J455,$H$10) -> 0 | K10: =COUNTIFS(K16:K280,$H$10) -> 0 | L10: =COUNTIFS(L16:L479,$H$10) -> 3 | M10: =COUNTIFS(M16:M479,$H$10) -> 3 | N10: =COUNTIFS(N16:N479,$H$10) -> 0 | O10: =COUNTIFS(O16:O479,$H$10) -> 3 | P10: =COUNTIFS(P16:P479,$H$10) -> 10 | Q10: =COUNTIFS(Q16:Q552,$H$10) -> 11 | R10: =COUNTIFS(R16:R479,$H$10) -> 10 | S10: =COUNTIFS(S16:S479,$H$10) -> 7 | T10: =COUNTIFS(T16:T479,$H$10) -> 11 | U10: =COUNTIFS(U16:U479,$H$10) -> 0 | V10: =COUNTIFS(V16:V479,$H$10) -> 3 | W10: =COUNTIFS(W16:W479,$H$10) -> 11 | X10: =COUNTIFS(X16:X479,$H$10) -> 9 | Y10: =COUNTIFS(Y16:Y479,$H$10) -> 9 | ... AL10: =COUNTIFS(AL16:AL479,$H$10) -> 3
B11: ca 18 | C11: Cơm Tăng Ca | D11: 95 | F11: =SUM(I11:AK11) -> 3147 | G11: Overtime meal | H11: Cơm Tăng Ca | I11: =COUNTIFS(I16:I455,$H$11) -> 13 | J11: =COUNTIFS(J16:J280,$H$11) -> 0 | K11: =COUNTIFS(K16:K280,$H$11) -> 0 | L11: =COUNTIFS(L16:L479,$H$11) -> 127 | M11: =COUNTIFS(M16:M479,$H$11) -> 15 | N11: =COUNTIFS(N16:N479,$H$11) -> 0 | O11: =COUNTIFS(O16:O479,$H$11) -> 121 | P11: =COUNTIFS(P16:P479,$H$11) -> 123 | Q11: =COUNTIFS(Q16:Q552,$H$11) -> 131 | R11: =COUNTIFS(R16:R479,$H$11) -> 103 | S11: =COUNTIFS(S16:S479,$H$11) -> 108 | T11: =COUNTIFS(T16:T479,$H$11) -> 17 | U11: =COUNTIFS(U16:U479,$H$11) -> 0 | V11: =COUNTIFS(V16:V479,$H$11) -> 116 | W11: =COUNTIFS(W16:W479,$H$11) -> 215 | X11: =COUNTIFS(X16:X479,$H$11) -> 221 | Y11: =COUNTIFS(Y16:Y479,$H$11) -> 229 | ... AL11: =COUNTIFS(AL16:AL479,$H$11) -> 148
G12: Vegan Dinner | H12: Cơm Chiều Chay | L12: =1+10 -> 11 | O12: =9 -> 9 | P12: =11 -> 11 | Q12: =11+1 -> 12 | R12: =4 -> 4 | S12: =11 -> 11 | V12: =8 -> 8 | W12: =5+7 -> 12 | X12: =11+6 -> 17 | Y12: =12+10 -> 22 | AC12: =15+9 -> 24 | AD12: =13+9 -> 22 | AE12: =14+8 -> 22 | AF12: =15+10 -> 25 | AG12: =8 -> 8 | AJ12: =12+7 -> 19 | AK12: =14+11 -> 25 | AL12: =1+10 -> 11
F13: =SUM(I13:AL13) -> 3469 | G13: Total | H13: Total | I13: =I9+I12 -> 16 | J13: =J9+J12 -> 0 | K13: =K9+K12 -> 0 | L13: =L9+L12 -> 130 | M13: =M9+M12 -> 18 | N13: =N9+N12 -> 0 | O13: =O9+O12 -> 124 | P13: =P9+P12 -> 133 | ... AL13: =AL9+AL12 -> 151 | AM13: =SUM(I13:AL13) -> 3469
A15: Status | B15: Code | C15: Fullname VN | D15: Department | E15: Section | F15: Place | I15: 34 | J15: 35 | K15: 36 | L15: 37 | N15: 40 | O15: 41 | P15: 42 | Q15: 43 | R15: 43 | S15: 44 | T15: 45 | U15: 46 | V15: 47 | W15: 48 | X15: 49 | Y15: 50 | Z15: 51 | AA15: 52 | AB15: 53 | AC15: 54 | AD15: 55 | AE15: 56 | AF15: 57 | AG15: 58 | AH15: 59 | AI15: 60 | AJ15: 61 | AK15: 62 | AM15: Total meals per day
A16: Active | B16: PTT0451 | C16: Trần Huy Cường | D16: Pro - Packaging | E16: Pro - Packaging | F16: Factory | L16: Cơm tăng ca | AM16: =COUNTA(I16:AL16) -> 1
A17: Active | B17: PTT0537 | C17: Nguyễn Quang Khải | D17: Pro - Aging | E17: Pro - Aging | F17: Factory | AH17: Cơm tăng ca | AM17: =COUNTA(I17:AL17) -> 1
A18: Active | B18: PTT0546 | C18: Nguyễn Phạm Kim Ngân | D18: Pro - Aging | E18: Pro - Aging | F18: Factory | AH18: Cơm tăng ca | AM18: =COUNTA(I18:AL18) -> 1
A19: Active | B19: PTT0556 | C19: Phan Thị Ngọc Mai | D19: Pro - Painting | E19: Pro - Painting | F19: Factory | AH19: Cơm tăng ca | AM19: =COUNTA(I19:AL19) -> 1
A20: Active | B20: PTT0572 | C20: Phan Tấn Hữu | D20: Pro - Packaging | E20: Pro - Packaging | F20: Factory | L20: Cơm tăng ca | AH20: Cơm tăng ca | AM20: =COUNTA(I20:AL20) -> 2
A21: Active | B21: PTT0583 | C21: Võ Thị Ánh Nguyệt | D21: Pro - Aging | E21: Pro - Aging | F21: Factory | L21: Cơm tăng ca | AM21: =COUNTA(I21:AL21) -> 1
A22: Active | B22: PTT0598 | C22: Nguyễn Hải Yến | D22: Pro - Packaging | E22: Pro - Packaging | F22: Factory | L22: Cơm tăng ca | AM22: =COUNTA(I22:AL22) -> 1
A23: Active | B23: PTT0615 | C23: Nguyễn Văn Phước | D23: Pro - Packaging | E23: Pro - Packaging | F23: Factory | L23: Cơm tăng ca | AM23: =COUNTA(I23:AL23) -> 1
A24: Active | B24: PTT0618 | C24: Từ Tuấn Tú | D24: Pro - Packaging | E24: Pro - Packaging | F24: Factory | L24: Cơm tăng ca | AM24: =COUNTA(I24:AL24) -> 1
A25: Active | B25: PTT0625 | C25: Nguyễn Thị Hồng Dung | D25: Pro - Packaging | E25: Pro - Packaging | F25: Factory | L25: Cơm tăng ca | AM25: =COUNTA(I25:AL25) -> 1
A26: Active | B26: PTT0633 | C26: Lý Văn Luôl | D26: Pro - Packaging | E26: Pro - Packaging | F26: Factory | L26: Cơm tăng ca | AM26: =COUNTA(I26:AL26) -> 1
A27: Active | B27: PTT0634 | C27: Khưu Thị Cẩm Lai | D27: Pro - Packaging | E27: Pro - Packaging | F27: Factory | L27: Cơm tăng ca | AM27: =COUNTA(I27:AL27) -> 1
A28: Active | B28: VCV0795 | C28: Trần Thị Quỳnh Như | D28: Pro - Packaging | E28: Pro - Packaging | F28: Factory | L28: Cơm tăng ca | Q28: Cơm tăng ca | V28: Cơm tăng ca | W28: Cơm tăng ca | Y28: Cơm tăng ca | Z28: Cơm tăng ca | AC28: Cơm tăng ca | AK28: Cơm tăng ca | AL28: Cơm tăng ca | AM28: =COUNTA(I28:AL28) -> 9
A29: Active | B29: PTT0639 | C29: Võ Thị Kim Chung | D29: Pro - Packaging | E29: Pro - Packaging | F29: Factory | L29: Cơm tăng ca | AM29: =COUNTA(I29:AL29) -> 1
A30: Active | B30: VCV0018 | C30: Vương Nhựt Lân | D30: Pro - Welding | E30: Pro - Welding | F30: Factory | L30: Cơm tăng ca | O30: Cơm tăng ca | P30: Cơm tăng ca | Q30: Cơm tăng ca | R30: Cơm tăng ca | S30: Cơm tăng ca | V30: Cơm tăng ca | W30: Cơm tăng ca | X30: Cơm tăng ca | Y30: Cơm tăng ca | Z30: Cơm tăng ca | AC30: Cơm tăng ca | AD30: Cơm tăng ca | AE30: Cơm tăng ca | AF30: Cơm tăng ca | AK30: Cơm tăng ca | AL30: Cơm tăng ca | AM30: =COUNTA(I30:AL30) -> 17
A31: Active | B31: VCV0025 | C31: Phạm Thị Ngọc Diễm | D31: Production | E31: Production | F31: Factory | P31: Cơm tăng ca | X31: Cơm tăng ca | Y31: Cơm tăng ca | Z31: Cơm tăng ca | AF31: Cơm tăng ca | AG31: Cơm tăng ca | AM31: =COUNTA(I31:AL31) -> 6
A32: Active | B32: VCV0028 | C32: Bùi Long Phi | D32: Pro - Polishing | E32: Pro - Polishing | F32: Factory | P32: Cơm tăng ca | R32: Cơm tăng ca | S32: Cơm tăng ca | V32: Cơm tăng ca | AC32: Cơm ca 2 | AD32: Cơm ca 2 | AE32: Cơm ca 2 | AF32: Cơm tăng ca | AG32: Cơm tăng ca | AH32: Cơm ca 2 | AJ32: Cơm ca 2 | AK32: Cơm ca 2 | AL32: Cơm tăng ca | AM32: =COUNTA(I32:AL32) -> 13
A33: Active | B33: VCV0029 | C33: Đoàn Thị Chút | D33: Pro - Packaging | E33: Pro - Packaging | F33: Factory | L33: Cơm tăng ca | O33: Cơm tăng ca | P33: Cơm tăng ca | Q33: Cơm tăng ca | S33: Cơm tăng ca | V33: Cơm tăng ca | W33: Cơm tăng ca | X33: Cơm tăng ca | Y33: Cơm tăng ca | Z33: Cơm tăng ca | AC33: Cơm tăng ca | AD33: Cơm tăng ca | AE33: Cơm tăng ca | AF33: Cơm tăng ca | AG33: Cơm tăng ca | AJ33: Cơm tăng ca | AK33: Cơm tăng ca | AL33: Cơm tăng ca | AM33: =COUNTA(I33:AL33) -> 18
A34: Active | B34: VCV0030 | C34: Thị Thủy | D34: Pro - Aging | E34: Pro - Aging | F34: Factory | W34: Cơm tăng ca | Y34: Cơm tăng ca | AC34: Cơm tăng ca | AD34: Cơm tăng ca | AE34: Cơm tăng ca | AF34: Cơm tăng ca | AJ34: Cơm tăng ca | AK34: Cơm tăng ca | AM34: =COUNTA(I34:AL34) -> 8
A35: Active | B35: VCV0031 | C35: Thòng Cooc Làn | D35: Pro - Aging | E35: Pro - Aging | F35: Factory | W35: Cơm tăng ca | Y35: Cơm tăng ca | AD35: Cơm tăng ca | AE35: Cơm tăng ca | AF35: Cơm tăng ca | AJ35: Cơm tăng ca | AK35: Cơm tăng ca | AM35: =COUNTA(I35:AL35) -> 7
A36: Active | B36: VCV0032 | C36: Nguyễn Thị Ngọc Trâm | D36: Pro - Aging | E36: Pro - Aging | F36: Factory | P36: Cơm Tăng Ca | W36: Cơm tăng ca | X36: Cơm tăng ca | Y36: Cơm tăng ca | AC36: Cơm tăng ca | AD36: Cơm tăng ca | AE36: Cơm tăng ca | AF36: Cơm tăng ca | AJ36: Cơm tăng ca | AK36: Cơm tăng ca | AM36: =COUNTA(I36:AL36) -> 10
A37: Active | B37: VCV0035 | C37: Hoàng Thanh Hoa | D37: Pro - Fabrication | E37: Pro - Fabrication | F37: Factory | O37: Cơm tăng ca | P37: Cơm Tăng Ca | Q37: Cơm tăng ca | S37: Cơm tăng ca | W37: Cơm tăng ca | Y37: Cơm tăng ca | Z37: Cơm tăng ca | AD37: Cơm tăng ca | AE37: Cơm tăng ca | AF37: Cơm tăng ca | AJ37: Cơm tăng ca | AL37: Cơm tăng ca | AM37: =COUNTA(I37:AL37) -> 12
A38: Active | B38: VCV0036 | C38: Bùi Hồng Giang | D38: Pro - Aging | E38: Pro - Aging | F38: Factory | W38: Cơm tăng ca | X38: Cơm tăng ca | Y38: Cơm tăng ca | AC38: Cơm tăng ca | AD38: Cơm tăng ca | AE38: Cơm tăng ca | AF38: Cơm tăng ca | AJ38: Cơm tăng ca | AK38: Cơm tăng ca | AM38: =COUNTA(I38:AL38) -> 9
A39: Active | B39: VCV0037 | C39: Hồ Thị Quỳnh Thoa | D39: Pro - Aging | E39: Pro - Aging | F39: Factory | W39: Cơm tăng ca | X39: Cơm tăng ca | Y39: Cơm tăng ca | AC39: Cơm tăng ca | AD39: Cơm tăng ca | AE39: Cơm tăng ca | AF39: Cơm tăng ca | AJ39: Cơm tăng ca | AK39: Cơm tăng ca | AM39: =COUNTA(I39:AL39) -> 9
A40: Active | B40: VCV0061 | C40: Trần Minh Công | D40: Pro - CNC | E40: Pro - CNC | F40: Factory | I40: Cơm tăng ca | L40: Cơm tăng ca | M40: Cơm tăng ca | O40: Cơm tăng ca | P40: Cơm tăng ca | Q40: Cơm tăng ca | S40: Cơm tăng ca | T40: Cơm tăng ca | V40: Cơm tăng ca | W40: Cơm tăng ca | X40: Cơm tăng ca | Y40: Cơm tăng ca | Z40: Cơm tăng ca | AA40: Cơm tăng ca | AD40: Cơm tăng ca | AE40: Cơm tăng ca | AF40: Cơm tăng ca | AG40: Cơm tăng ca | AH40: Cơm tăng ca | AJ40: Cơm tăng ca | AK40: Cơm tăng ca | AL40: Cơm tăng ca | AM40: =COUNTA(I40:AL40) -> 22
A41: Active | B41: VCV0063 | C41: Trần Cường | D41: PMC - Quality | E41: PMC - Quality | F41: Factory | L41: Cơm tăng ca | O41: Cơm tăng ca | T41: Cơm tăng ca | V41: Cơm tăng ca | X41: Cơm tăng ca | Z41: Cơm tăng ca | AC41: Cơm tăng ca | AE41: Cơm tăng ca | AG41: Cơm tăng ca | AJ41: Cơm tăng ca | AL41: Cơm tăng ca | AM41: =COUNTA(I41:AL41) -> 11
A42: Active | B42: VCV0065 | C42: Nguyễn Hoàng Vũ | D42: Pro - Manual Lathe | E42: Pro - Manual Lathe | F42: Factory | L42: Cơm tăng ca | O42: Cơm tăng ca | P42: Cơm tăng ca | Q42: Cơm tăng ca | R42: Cơm tăng ca | V42: Cơm tăng ca | W42: Cơm tăng ca | X42: Cơm tăng ca | Y42: Cơm tăng ca | Z42: Cơm tăng ca | AD42: Cơm tăng ca | AE42: Cơm tăng ca | AF42: Cơm tăng ca | AJ42: Cơm tăng ca | AK42: Cơm tăng ca | AL42: Cơm tăng ca | AM42: =COUNTA(I42:AL42) -> 16
A43: Active | B43: VCV0069 | C43: Đinh Thị Ngọc Thùy | D43: Pro - Painting | E43: Pro - Painting | F43: Factory | L43: Cơm tăng ca | O43: Cơm tăng ca | Y43: Cơm tăng ca | Z43: Cơm tăng ca | AC43: Cơm tăng ca | AD43: Cơm tăng ca | AE43: Cơm tăng ca | AF43: Cơm tăng ca | AJ43: Cơm tăng ca | AK43: Cơm tăng ca | AM43: =COUNTA(I43:AL43) -> 10
...

Sheet HHVCV
I1: 46266 | J1: 46267 | K1: 46268 | L1: 46269 | M1: 46270 | N1: 46271 | O1: 46272 | P1: 46273 | Q1: 46274 | R1: 46275 | S1: 46276 | T1: 46277 | U1: 46278 | V1: 46279 | W1: 46280 | X1: 46281 | Y1: 46282 | Z1: 46283 | AA1: 46284 | AB1: 46285 | AC1: 46286 | AD1: 46287 | AE1: 46288 | AF1: 46289 | AG1: 46290 | AH1: 46291 | AI1: 46292 | AJ1: 46293 | AK1: 46294 | AL1: 46295
G2: Shift 1 + normal shift | H2: Ca sáng | I2: =SUM(I3:I5) -> 0 | J2: =SUM(J3:J5) -> 0 | K2: =SUM(K3:K5) -> 0 | L2: =SUM(L3:L5) -> 0 | M2: =SUM(M3:M5) -> 0 | N2: =SUM(N3:N5) -> 0 | O2: =SUM(O3:O5) -> 0 | P2: =SUM(P3:P5) -> 0 | ... AL2: =SUM(AL3:AL5) -> 37
G3: DS- CN food | H3: Sáng - Trung | I3: =COUNTIFS(I$11:I$460,$H3) -> 0 | J3: =COUNTIFS(J$11:J$460,$H3) -> 0 | K3: =COUNTIFS(K$11:K$460,$H3) -> 0 | L3: =COUNTIFS(L$11:L$460,$H3) -> 0 | M3: =COUNTIFS(M$11:M$460,$H3) -> 0 | N3: =COUNTIFS(N$11:N$460,$H3) -> 0 | O3: =COUNTIFS(O$11:O$460,$H3) -> 0 | P3: =COUNTIFS(P$11:P$460,$H3) -> 0 | ... AL3: =COUNTIFS(AL$11:AL$460,$H3) -> 9
G4: DS- VN food | H4: Sáng - Mặn - Xưởng | I4: =COUNTIFS(I$11:I$460,$H4)-I5 -> 0 | J4: =COUNTIFS(J$11:J$460,$H4)-J5 -> 0 | K4: =COUNTIFS(K$11:K$460,$H4)-K5 -> 0 | L4: =COUNTIFS(L$11:L$460,$H4)-L5 -> 0 | M4: =COUNTIFS(M$11:M$460,$H4)-M5 -> 0 | N4: =COUNTIFS(N$11:N$460,$H4)-N5 -> 0 | O4: =COUNTIFS(O$11:O$460,$H4)-O5 -> 0 | P4: =COUNTIFS(P$11:P$460,$H4)-P5 -> 0 | ... AL4: =COUNTIFS(AL$11:AL$460,$H4)-AL5 -> 28
G5: DS- Vegetarian rice | H5: Sáng - Chay - Xưởng | AI5: =8 -> 8
E6: =SUM(I6:AL6) -> 430 | I6: =SUM(I7:I8) -> 0 | J6: =SUM(J7:J8) -> 0 | K6: =SUM(K7:K8) -> 0 | L6: =SUM(L7:L8) -> 0 | M6: =SUM(M7:M8) -> 0 | N6: =SUM(N7:N8) -> 0 | O6: =SUM(O7:O8) -> 0 | P6: =SUM(P7:P8) -> 0 | ... AL6: =SUM(AL7:AL8) -> 37
D7: 57 | E7: =SUM(I7:AL7) -> 107 | G7: Total Expat Meals | I7: =I3 -> 0 | J7: =J3 -> 0 | K7: =K3 -> 0 | L7: =L3 -> 0 | M7: =M3 -> 0 | N7: =N3 -> 0 | O7: =O3 -> 0 | P7: =P3 -> 0 | ... AL7: =AL3 -> 9
E8: =SUM(I8:AL8) -> 323 | G8: Total Vietnamese Meals | I8: =I2-I3 -> 0 | J8: =J2-J3 -> 0 | K8: =K2-K3 -> 0 | L8: =L2-L3 -> 0 | M8: =M2-M3 -> 0 | N8: =N2-N3 -> 0 | O8: =O2-O3 -> 0 | P8: =P2-P3 -> 0 | ... AL8: =AL2-AL3 -> 28
AM10: =E6-SUM(AM12:AM352) -> 0
A11: Status | B11: Code | C11: Fullname VN | D11: Department | E11: Section | F11: Place | H11: Last day | AM11: Total meals per day
A12: Active | B12: 26000 | C12: Nguyễn Thị Ngọc Nữ | D12: HHVCV | F12: Dầu Giây | AD12: Sáng - Mặn - Xưởng | AE12: Sáng - Mặn - Xưởng | AF12: Sáng - Mặn - Xưởng | AG12: Sáng - Mặn - Xưởng | AH12: Sáng - Mặn - Xưởng | AJ12: Sáng - Mặn - Xưởng | AK12: Sáng - Mặn - Xưởng | AL12: Sáng - Mặn - Xưởng | AM12: =COUNTA(I12:AL12)-COUNTIF(I12:AL12,"CT") -> 8
A13: Active | B13: 26001 | C13: Trần Minh Thiện | D13: HHVCV | F13: Dầu Giây | AD13: Sáng - Mặn - Xưởng | AE13: Sáng - Mặn - Xưởng | AF13: Sáng - Mặn - Xưởng | AG13: Sáng - Mặn - Xưởng | AH13: Sáng - Mặn - Xưởng | AJ13: Sáng - Mặn - Xưởng | AK13: Sáng - Mặn - Xưởng | AL13: Sáng - Mặn - Xưởng | AM13: =COUNTA(I13:AL13)-COUNTIF(I13:AL13,"CT") -> 8
A14: Active | B14: 26004 | C14: Trần Thị Oanh Đào | D14: HHVCV | F14: Dầu Giây | AD14: Sáng - Mặn - Xưởng | AE14: Sáng - Mặn - Xưởng | AF14: Sáng - Mặn - Xưởng | AG14: Sáng - Mặn - Xưởng | AH14: Sáng - Mặn - Xưởng | AK14: Sáng - Mặn - Xưởng | AL14: Sáng - Mặn - Xưởng | AM14: =COUNTA(I14:AL14)-COUNTIF(I14:AL14,"CT") -> 7
A15: Active | B15: 26005 | C15: Nguyễn Minh Lâm | D15: HHVCV | F15: Dầu Giây | AD15: Sáng - Mặn - Xưởng | AE15: Sáng - Mặn - Xưởng | AF15: Sáng - Mặn - Xưởng | AG15: Sáng - Mặn - Xưởng | AH15: Sáng - Mặn - Xưởng | AJ15: Sáng - Mặn - Xưởng | AK15: Sáng - Mặn - Xưởng | AL15: Sáng - Mặn - Xưởng | AM15: =COUNTA(I15:AL15)-COUNTIF(I15:AL15,"CT") -> 8
A16: Active | B16: 26006 | C16: Nguyễn Ngọc Quỳnh Như | D16: HHVCV | F16: Dầu Giây | AD16: Sáng - Mặn - Xưởng | AE16: Sáng - Mặn - Xưởng | AF16: Sáng - Mặn - Xưởng | AG16: Sáng - Mặn - Xưởng | AH16: Sáng - Mặn - Xưởng | AJ16: Sáng - Mặn - Xưởng | AK16: Sáng - Mặn - Xưởng | AL16: Sáng - Mặn - Xưởng | AM16: =COUNTA(I16:AL16)-COUNTIF(I16:AL16,"CT") -> 8
A17: Active | B17: 26007 | C17: Nguyễn Văn Duyên | D17: HHVCV | F17: Dầu Giây | AD17: Sáng - Mặn - Xưởng | AE17: Sáng - Mặn - Xưởng | AF17: Sáng - Mặn - Xưởng | AG17: Sáng - Mặn - Xưởng | AH17: Sáng - Mặn - Xưởng | AJ17: Sáng - Mặn - Xưởng | AK17: Sáng - Mặn - Xưởng | AL17: Sáng - Mặn - Xưởng | AM17: =COUNTA(I17:AL17)-COUNTIF(I17:AL17,"CT") -> 8
A18: Active | B18: 26009 | C18: Trần Minh Kim | D18: HHVCV | F18: Dầu Giây | AD18: Sáng - Mặn - Xưởng | AE18: Sáng - Mặn - Xưởng | AF18: Sáng - Mặn - Xưởng | AG18: Sáng - Mặn - Xưởng | AH18: Sáng - Mặn - Xưởng | AJ18: Sáng - Mặn - Xưởng | AK18: Sáng - Mặn - Xưởng | AL18: Sáng - Mặn - Xưởng | AM18: =COUNTA(I18:AL18)-COUNTIF(I18:AL18,"CT") -> 8
A19: Active | B19: 26010 | C19: Phan Huynh Ngọc Diễm | D19: HHVCV | F19: Dầu Giây | AD19: Sáng - Mặn - Xưởng | AE19: Sáng - Mặn - Xưởng | AF19: Sáng - Mặn - Xưởng | AG19: Sáng - Mặn - Xưởng | AH19: Sáng - Mặn - Xưởng | AJ19: Sáng - Mặn - Xưởng | AK19: Sáng - Mặn - Xưởng | AM19: =COUNTA(I19:AL19)-COUNTIF(I19:AL19,"CT") -> 7
A20: Active | B20: 26011 | C20: Lê Đức Quyền | D20: HHVCV | F20: Dầu Giây | AD20: Sáng - Mặn - Xưởng | AE20: Sáng - Mặn - Xưởng | AF20: Sáng - Mặn - Xưởng | AG20: Sáng - Mặn - Xưởng | AH20: Sáng - Mặn - Xưởng | AK20: Sáng - Mặn - Xưởng | AL20: Sáng - Mặn - Xưởng | AM20: =COUNTA(I20:AL20)-COUNTIF(I20:AL20,"CT") -> 7
A21: Active | B21: 26012 | C21: Nguyễn Văn Thông | D21: HHVCV | F21: Dầu Giây | AD21: Sáng - Mặn - Xưởng | AE21: Sáng - Mặn - Xưởng | AF21: Sáng - Mặn - Xưởng | AG21: Sáng - Mặn - Xưởng | AH21: Sáng - Mặn - Xưởng | AK21: Sáng - Mặn - Xưởng | AL21: Sáng - Mặn - Xưởng | AM21: =COUNTA(I21:AL21)-COUNTIF(I21:AL21,"CT") -> 7
A22: Active | B22: 26013 | C22: Lê Phạm Như Quỳnh | D22: HHVCV | F22: Dầu Giây | AD22: Sáng - Mặn - Xưởng | AE22: Sáng - Mặn - Xưởng | AF22: Sáng - Mặn - Xưởng | AG22: Sáng - Mặn - Xưởng | AH22: Sáng - Mặn - Xưởng | AJ22: Sáng - Mặn - Xưởng | AK22: Sáng - Mặn - Xưởng | AL22: Sáng - Mặn - Xưởng | AM22: =COUNTA(I22:AL22)-COUNTIF(I22:AL22,"CT") -> 8
A23: Active | B23: 26014 | C23: Trương Vũ Thiên Nhi | D23: HHVCV | F23: Dầu Giây | AE23: Sáng - Mặn - Xưởng | AF23: Sáng - Mặn - Xưởng | AK23: Sáng - Mặn - Xưởng | AL23: Sáng - Mặn - Xưởng | AM23: =COUNTA(I23:AL23)-COUNTIF(I23:AL23,"CT") -> 4
A24: Active | B24: 26016 | C24: Phạm Anh Vũ | D24: HHVCV | F24: Dầu Giây | AD24: Sáng - Mặn - Xưởng | AE24: Sáng - Mặn - Xưởng | AF24: Sáng - Mặn - Xưởng | AG24: Sáng - Mặn - Xưởng | AH24: Sáng - Mặn - Xưởng | AJ24: Sáng - Mặn - Xưởng | AK24: Sáng - Mặn - Xưởng | AL24: Sáng - Mặn - Xưởng | AM24: =COUNTA(I24:AL24)-COUNTIF(I24:AL24,"CT") -> 8
A25: Active | B25: 26017 | C25: Bùi Vũ Bảo Trâm | D25: HHVCV | F25: Dầu Giây | AD25: Sáng - Mặn - Xưởng | AF25: Sáng - Mặn - Xưởng | AG25: Sáng - Mặn - Xưởng | AH25: Sáng - Mặn - Xưởng | AK25: Sáng - Mặn - Xưởng | AL25: Sáng - Mặn - Xưởng | AM25: =COUNTA(I25:AL25)-COUNTIF(I25:AL25,"CT") -> 6
A26: Active | B26: 26003 | C26: Thòng Hoàng Long | D26: HHVCV | F26: Dầu Giây | AD26: Sáng - Mặn - Xưởng | AE26: Sáng - Mặn - Xưởng | AF26: Sáng - Mặn - Xưởng | AG26: Sáng - Mặn - Xưởng | AH26: Sáng - Mặn - Xưởng | AJ26: Sáng - Mặn - Xưởng | AK26: Sáng - Mặn - Xưởng | AL26: Sáng - Mặn - Xưởng | AM26: =COUNTA(I26:AL26)-COUNTIF(I26:AL26,"CT") -> 8
A27: Active | B27: 26002 | C27: Trần Hoài Yến Nhi | D27: HHVCV | F27: Dầu Giây | AD27: Sáng - Mặn - Xưởng | AE27: Sáng - Mặn - Xưởng | AF27: Sáng - Mặn - Xưởng | AG27: Sáng - Mặn - Xưởng | AH27: Sáng - Mặn - Xưởng | AJ27: Sáng - Mặn - Xưởng | AK27: Sáng - Mặn - Xưởng | AL27: Sáng - Mặn - Xưởng | AM27: =COUNTA(I27:AL27)-COUNTIF(I27:AL27,"CT") -> 8
A28: Active | C28: Phạm Thị Thuỳ Tiên | D28: HHVCV | F28: Dầu Giây | AD28: Sáng - Mặn - Xưởng | AE28: Sáng - Mặn - Xưởng | AF28: Sáng - Mặn - Xưởng | AG28: Sáng - Mặn - Xưởng | AH28: Sáng - Mặn - Xưởng | AJ28: Sáng - Mặn - Xưởng | AK28: Sáng - Mặn - Xưởng | AL28: Sáng - Mặn - Xưởng | AM28: =COUNTA(I28:AL28)-COUNTIF(I28:AL28,"CT") -> 8
A29: Active | C29: Võ Minh Đạt | D29: HHVCV | F29: Dầu Giây | AD29: Sáng - Mặn - Xưởng | AE29: Sáng - Mặn - Xưởng | AF29: Sáng - Mặn - Xưởng | AK29: Sáng - Mặn - Xưởng | AL29: Sáng - Mặn - Xưởng | AM29: =COUNTA(I29:AL29)-COUNTIF(I29:AL29,"CT") -> 5
A30: Active | B30: VCV0320 | C30: Đõ Lệ Ngọc | D30: PMC - WH | E30: PMC - WH | F30: Dầu Giây | AD30: Sáng - Mặn - Xưởng | AE30: Sáng - Mặn - Xưởng | AF30: Sáng - Mặn - Xưởng | AG30: Sáng - Mặn - Xưởng | AH30: Sáng - Mặn - Xưởng | AJ30: Sáng - Mặn - Xưởng | AK30: Sáng - Mặn - Xưởng | AL30: Sáng - Mặn - Xưởng | AM30: =COUNTA(I30:AL30)-COUNTIF(I30:AL30,"CT") -> 8
A31: Active | B31: VCV0788 | C31: Diệu Ngọc | D31: PMC - WH | E31: PMC - WH | F31: Dầu Giây | AD31: Sáng - Mặn - Xưởng | AE31: Sáng - Mặn - Xưởng | AF31: Sáng - Mặn - Xưởng | AG31: Sáng - Mặn - Xưởng | AH31: Sáng - Mặn - Xưởng | AJ31: Sáng - Mặn - Xưởng | AK31: Sáng - Mặn - Xưởng | AL31: Sáng - Mặn - Xưởng | AM31: =COUNTA(I31:AL31)-COUNTIF(I31:AL31,"CT") -> 8
A32: Active | B32: VCV0719 | C32: Trịnh Xuân Trường | D32: PMC - WH | E32: PMC - WH | F32: Dầu Giây | AD32: Sáng - Mặn - Xưởng | AE32: Sáng - Mặn - Xưởng | AF32: Sáng - Mặn - Xưởng | AG32: Sáng - Mặn - Xưởng | AH32: Sáng - Mặn - Xưởng | AJ32: Sáng - Mặn - Xưởng | AK32: Sáng - Mặn - Xưởng | AL32: Sáng - Mặn - Xưởng | AM32: =COUNTA(I32:AL32)-COUNTIF(I32:AL32,"CT") -> 8
A33: Active | B33: VCV0750 | C33: Huỳnh Khang Duy | D33: PMC - WH | E33: PMC - WH | F33: Dầu Giây | AD33: Sáng - Mặn - Xưởng | AE33: Sáng - Mặn - Xưởng | AF33: Sáng - Mặn - Xưởng | AG33: Sáng - Mặn - Xưởng | AH33: Sáng - Mặn - Xưởng | AJ33: Sáng - Mặn - Xưởng | AK33: Sáng - Mặn - Xưởng | AL33: Sáng - Mặn - Xưởng | AM33: =COUNTA(I33:AL33)-COUNTIF(I33:AL33,"CT") -> 8
A34: Active | B34: VCV0623 | C34: Phạm Văn Tuấn | D34: PMC - WH | E34: PMC - WH | F34: Dầu Giây | AD34: Sáng - Mặn - Xưởng | AE34: Sáng - Mặn - Xưởng | AF34: Sáng - Mặn - Xưởng | AG34: Sáng - Mặn - Xưởng | AJ34: Sáng - Mặn - Xưởng | AK34: Sáng - Mặn - Xưởng | AL34: Sáng - Mặn - Xưởng | AM34: =COUNTA(I34:AL34)-COUNTIF(I34:AL34,"CT") -> 7
A35: Active | B35: VCV0787 | C35: Nguyễn Phúc Ân | D35: PMC - WH | E35: PMC - WH | F35: Dầu Giây | AD35: Sáng - Mặn - Xưởng | AE35: Sáng - Mặn - Xưởng | AL35: Sáng - Mặn - Xưởng | AM35: =COUNTA(I35:AL35)-COUNTIF(I35:AL35,"CT") -> 3
A36: Active | B36: VCV0756 | C36: Lường Chắn Hoa | D36: PMC - WH | E36: PMC - WH | F36: Dầu Giây | AD36: Sáng - Mặn - Xưởng | AE36: Sáng - Mặn - Xưởng | AF36: Sáng - Mặn - Xưởng | AG36: Sáng - Mặn - Xưởng | AH36: Sáng - Mặn - Xưởng | AJ36: Sáng - Mặn - Xưởng | AK36: Sáng - Mặn - Xưởng | AL36: Sáng - Mặn - Xưởng | AM36: =COUNTA(I36:AL36)-COUNTIF(I36:AL36,"CT") -> 8
A37: Active | C37: Trần Minh Hiếu | D37: PMC - WH | E37: PMC - WH | F37: Dầu Giây | AD37: Sáng - Mặn - Xưởng | AE37: Sáng - Mặn - Xưởng | AF37: Sáng - Mặn - Xưởng | AG37: Sáng - Mặn - Xưởng | AH37: Sáng - Mặn - Xưởng | AJ37: Sáng - Mặn - Xưởng | AK37: Sáng - Mặn - Xưởng | AL37: Sáng - Mặn - Xưởng | AM37: =COUNTA(I37:AL37)-COUNTIF(I37:AL37,"CT") -> 8
A38: Active | B38: VCV0444 | C38: Lê Doãn Hội | D38: PMC - WH | E38: PMC - WH | F38: Dầu Giây | AE38: Sáng - Mặn - Xưởng | AG38: Sáng - Mặn - Xưởng | AH38: Sáng - Mặn - Xưởng | AJ38: Sáng - Mặn - Xưởng | AK38: Sáng - Mặn - Xưởng | AL38: Sáng - Mặn - Xưởng | AM38: =COUNTA(I38:AL38)-COUNTIF(I38:AL38,"CT") -> 6
A39: Active | B39: VCV0501 | C39: Nguyễn Văn Phước | D39: PMC - WH | E39: PMC - WH | F39: Dầu Giây | AD39: Sáng - Mặn - Xưởng | AG39: Sáng - Mặn - Xưởng | AH39: Sáng - Mặn - Xưởng | AJ39: Sáng - Mặn - Xưởng | AK39: Sáng - Mặn - Xưởng | AM39: =COUNTA(I39:AL39)-COUNTIF(I39:AL39,"CT") -> 5
A40: Active | B40: VCV0770 | C40: Tsần Thị Hồng Linh | D40: PMC - WH | E40: PMC - WH | F40: Dầu Giây | AG40: Sáng - Mặn - Xưởng | AM40: =COUNTA(I40:AL40)-COUNTIF(I40:AL40,"CT") -> 1
A41: Active | C41: Vũ Đại Thắng | D41: PMC - WH | E41: PMC - WH | F41: Dầu Giây | AK41: Sáng - Mặn - Xưởng | AM41: =COUNTA(I41:AL41)-COUNTIF(I41:AL41,"CT") -> 1
...

Sheet HHVCV - Tăng ca
I1: 46266 | J1: 46267 | K1: 46268 | L1: 46269 | M1: 46270 | N1: 46271 | O1: 46272 | P1: 46273 | Q1: 46274 | R1: 46275 | S1: 46276 | T1: 46277 | U1: 46278 | V1: 46279 | W1: 46280 | X1: 46281 | Y1: 46282 | Z1: 46283 | AA1: 46284 | AB1: 46285 | AC1: 46286 | AD1: 46287 | AE1: 46288 | AF1: 46289 | AG1: 46290 | AH1: 46291 | AI1: 46292 | AJ1: 46293 | AK1: 46294 | AL1: 46295
J2: =SUM(J3:J7) -> 0 | K2: =SUM(K3:K7) -> 0 | L2: =SUM(L3:L7) -> 0 | N2: =SUM(N3:N7) -> 0 | O2: =SUM(O3:O7) -> 0 | P2: =SUM(P3:P7) -> 0 | Q2: =SUM(Q3:Q7) -> 0 | R2: =SUM(R3:R7) -> 0 | S2: =SUM(S3:S7) -> 0 | T2: =SUM(T3:T7) -> 0 | U2: =SUM(U3:U7) -> 0 | ... AK2: =SUM(AK3:AK7) -> 0
I3: =COUNTIFS(I$15:I$102,$H3) -> 0 | J3: =COUNTIFS(J$15:J$102,$H3) -> 0 | K3: =COUNTIFS(K$15:K$102,$H3) -> 0 | L3: =COUNTIFS(L$15:L$102,$H3) -> 0 | N3: =COUNTIFS(N$15:N$102,$H3) -> 0 | O3: =COUNTIFS(O$15:O$102,$H3) -> 0 | P3: =COUNTIFS(P$15:P$102,$H3) -> 0 | Q3: =COUNTIFS(Q$15:Q$102,$H3) -> 0 | R3: =COUNTIFS(R$15:R$102,$H3) -> 0 | S3: =COUNTIFS(S$15:S$102,$H3) -> 0 | T3: =COUNTIFS(T$15:T$102,$H3) -> 0 | U3: =COUNTIFS(U$15:U$102,$H3) -> 0 | ... AK3: =COUNTIFS(AK$15:AK$102,$H3) -> 0
I4: =COUNTIFS(I$15:I$102,$H4)-I5 -> 0 | J4: =COUNTIFS(J$15:J$102,$H4)-J5 -> 0 | K4: =COUNTIFS(K$15:K$102,$H4)-K5 -> 0 | L4: =COUNTIFS(L$15:L$102,$H4)-L5 -> 0 | N4: =COUNTIFS(N$15:N$102,$H4)-N5 -> 0 | O4: =COUNTIFS(O$15:O$102,$H4)-O5 -> 0 | P4: =COUNTIFS(P$15:P$102,$H4)-P5 -> 0 | Q4: =COUNTIFS(Q$15:Q$102,$H4)-Q5 -> 0 | R4: =COUNTIFS(R$15:R$102,$H4)-R5 -> 0 | S4: =COUNTIFS(S$15:S$102,$H4)-S5 -> 0 | T4: =COUNTIFS(T$15:T$102,$H4)-T5 -> 0 | U4: =COUNTIFS(U$15:U$102,$H4)-U5 -> 0 | ... AK4: =COUNTIFS(AK$15:AK$102,$H4)-AK5 -> 0
G7: DS- Vegetarian rice | H7: Cơm ca đêm
G8: Shift 2 | H8: Ca chiều | I8: =I9+I12 -> 0 | J8: =J9+J12 -> 0 | K8: =K9+K12 -> 0 | L8: =L9+L12 -> 0 | M8: =M9+M12 -> 0 | N8: =N9+N12 -> 0 | O8: =O9+O12 -> 0 | P8: =P9+P12 -> 0 | ... AK8: =AK9+AK12 -> 24
G9: Savory Dinner | H9: Cơm Chiều Mặn | I9: =SUM(I10:I11)-I12 -> 0 | J9: =SUM(J10:J11)-J12 -> 0 | K9: =SUM(K10:K11)-K12 -> 0 | L9: =SUM(L10:L11)-L12 -> 0 | M9: =SUM(M10:M11)-M12 -> 0 | N9: =SUM(N10:N11)-N12 -> 0 | O9: =SUM(O10:O11)-O12 -> 0 | P9: =SUM(P10:P11)-P12 -> 0 | ... AL9: =SUM(AL10:AL11)-AL12 -> 21
E10: 45 | F10: =SUM(I10:AL10) -> 67 | G10: Overtime meal | H10: Cơm tăng Ca - TQ | I10: =COUNTIFS($I15:I$456,$H$10) -> 0 | J10: =COUNTIFS(J16:J456,$H$10) -> 0 | K10: =COUNTIFS(K16:K281,$H$10) -> 0 | L10: =COUNTIFS(L16:L480,$H$10) -> 0 | M10: =COUNTIFS(M16:M480,$H$10) -> 0 | N10: =COUNTIFS(N16:N480,$H$10) -> 0 | O10: =COUNTIFS(O16:O480,$H$10) -> 0 | P10: =COUNTIFS(P16:P480,$H$10) -> 0 | Q10: =COUNTIFS(Q16:Q553,$H$10) -> 0 | R10: =COUNTIFS(R16:R480,$H$10) -> 0 | S10: =COUNTIFS(S16:S480,$H$10) -> 0 | T10: =COUNTIFS(T16:T480,$H$10) -> 0 | U10: =COUNTIFS(U16:U480,$H$10) -> 0 | V10: =COUNTIFS(V16:V480,$H$10) -> 0 | W10: =COUNTIFS(W16:W480,$H$10) -> 0 | X10: =COUNTIFS(X16:X480,$H$10) -> 0 | Y10: =COUNTIFS(Y16:Y480,$H$10) -> 0 | ... AL10: =COUNTIFS(AL16:AL480,$H$10) -> 5
F11: =SUM(I11:AL11) -> 65 | G11: Overtime meal | H11: Cơm Tăng Ca | I11: =COUNTIFS(I16:I456,$H$11) -> 0 | J11: =COUNTIFS(J16:J281,$H$11) -> 0 | K11: =COUNTIFS(K16:K281,$H$11) -> 0 | L11: =COUNTIFS(L16:L480,$H$11) -> 0 | M11: =COUNTIFS(M16:M480,$H$11) -> 0 | N11: =COUNTIFS(N16:N480,$H$11) -> 0 | O11: =COUNTIFS(O16:O480,$H$11) -> 0 | P11: =COUNTIFS(P16:P480,$H$11) -> 0 | Q11: =COUNTIFS(Q16:Q553,$H$11) -> 0 | R11: =COUNTIFS(R16:R480,$H$11) -> 0 | S11: =COUNTIFS(S16:S480,$H$11) -> 0 | T11: =COUNTIFS(T16:T480,$H$11) -> 0 | U11: =COUNTIFS(U16:U480,$H$11) -> 0 | V11: =COUNTIFS(V16:V480,$H$11) -> 0 | W11: =COUNTIFS(W16:W480,$H$11) -> 0 | X11: =COUNTIFS(X16:X480,$H$11) -> 0 | Y11: =COUNTIFS(Y16:Y480,$H$11) -> 0 | ... AL11: =COUNTIFS(AL16:AL480,$H$11) -> 16
G12: Vegan Dinner | H12: Cơm Chiều Chay
F13: =SUM(I13:AL13) -> 132 | G13: Total | H13: Total | I13: =I9+I12 -> 0 | J13: =J9+J12 -> 0 | K13: =K9+K12 -> 0 | L13: =L9+L12 -> 0 | M13: =M9+M12 -> 0 | N13: =N9+N12 -> 0 | O13: =O9+O12 -> 0 | P13: =P9+P12 -> 0 | ... AL13: =AL9+AL12 -> 21 | AM13: =SUM(I13:AL13) -> 132
A15: Status | B15: Code | C15: Fullname VN | D15: Department | E15: Section | F15: Place | I15: 34 | J15: 35 | K15: 36 | L15: 37 | N15: 40 | O15: 41 | P15: 42 | Q15: 43 | R15: 43 | S15: 44 | T15: 45 | U15: 46 | V15: 47 | W15: 48 | X15: 49 | Y15: 50 | Z15: 51 | AA15: 52 | AB15: 53 | AC15: 54 | AD15: 55 | AE15: 56 | AF15: 57 | AG15: 58 | AH15: 59 | AI15: 60 | AJ15: 61 | AK15: 62 | AM15: Total meals per day
A16: Active | B16: 26000 | C16: Nguyễn Thị Ngọc Nữ | D16: HHVCV | F16: Dầu Giây | AE16: Cơm tăng ca | AJ16: Cơm tăng ca | AK16: Cơm tăng ca | AL16: Cơm Tăng Ca | AM16: =COUNTA(I16:AL16) -> 4
A17: Active | B17: 26001 | C17: Trần Minh Thiện | D17: HHVCV | F17: Dầu Giây | AJ17: Cơm tăng ca | AK17: Cơm tăng ca | AL17: Cơm Tăng Ca | AM17: =COUNTA(I17:AL17) -> 3
A18: Active | B18: 26004 | C18: Trần Thị Oanh Đào | D18: HHVCV | F18: Dầu Giây | AE18: Cơm tăng ca | AK18: Cơm tăng ca | AL18: Cơm Tăng Ca | AM18: =COUNTA(I18:AL18) -> 3
A19: Active | B19: 26005 | C19: Nguyễn Minh Lâm | D19: HHVCV | F19: Dầu Giây | AE19: Cơm tăng ca | AJ19: Cơm tăng ca | AK19: Cơm tăng ca | AL19: Cơm Tăng Ca | AM19: =COUNTA(I19:AL19) -> 4
A20: Active | B20: 26006 | C20: Nguyễn Ngọc Quỳnh Như | D20: HHVCV | F20: Dầu Giây | AE20: Cơm tăng ca | AJ20: Cơm tăng ca | AK20: Cơm tăng ca | AL20: Cơm Tăng Ca | AM20: =COUNTA(I20:AL20) -> 4
A21: Active | B21: 26007 | C21: Nguyễn Văn Duyên | D21: HHVCV | F21: Dầu Giây | AE21: Cơm tăng ca | AJ21: Cơm tăng ca | AK21: Cơm tăng ca | AL21: Cơm Tăng Ca | AM21: =COUNTA(I21:AL21) -> 4
A22: Active | B22: 26009 | C22: Trần Minh Kim | D22: HHVCV | F22: Dầu Giây | AE22: Cơm tăng ca | AJ22: Cơm tăng ca | AK22: Cơm tăng ca | AL22: Cơm Tăng Ca | AM22: =COUNTA(I22:AL22) -> 4
A23: Active | B23: 26010 | C23: Phan Huynh Ngọc Diễm | D23: HHVCV | F23: Dầu Giây | AJ23: Cơm tăng ca | AL23: Cơm Tăng Ca | AM23: =COUNTA(I23:AL23) -> 2
A24: Active | B24: 26011 | C24: Lê Đức Quyền | D24: HHVCV | F24: Dầu Giây | AE24: Cơm tăng ca | AK24: Cơm tăng ca | AL24: Cơm Tăng Ca | AM24: =COUNTA(I24:AL24) -> 3
A25: Active | B25: 26012 | C25: Nguyễn Văn Thông | D25: HHVCV | F25: Dầu Giây | AE25: Cơm tăng ca | AK25: Cơm tăng ca | AL25: Cơm Tăng Ca | AM25: =COUNTA(I25:AL25) -> 3
A26: Active | B26: 26013 | C26: Lê Phạm Như Quỳnh | D26: HHVCV | F26: Dầu Giây | AJ26: Cơm tăng ca | AK26: Cơm tăng ca | AL26: Cơm Tăng Ca | AM26: =COUNTA(I26:AL26) -> 3
A27: Active | B27: 26014 | C27: Trương Vũ Thiên Nhi | D27: HHVCV | F27: Dầu Giây | AE27: Cơm tăng ca | AJ27: Cơm tăng ca | AL27: Cơm Tăng Ca | AM27: =COUNTA(I27:AL27) -> 3
A28: Active | B28: 26016 | C28: Phạm Anh Vũ | D28: HHVCV | F28: Dầu Giây | AE28: Cơm tăng ca | AJ28: Cơm tăng ca | AK28: Cơm tăng ca | AL28: Cơm Tăng Ca | AM28: =COUNTA(I28:AL28) -> 4
A29: Active | B29: 26017 | C29: Bùi Vũ Bảo Trâm | D29: HHVCV | F29: Dầu Giây | AE29: Cơm tăng ca | AK29: Cơm tăng ca | AL29: Cơm Tăng Ca | AM29: =COUNTA(I29:AL29) -> 3
A30: Active | B30: 26003 | C30: Thòng Hoàng Long | D30: HHVCV | F30: Dầu Giây | AE30: Cơm tăng ca | AJ30: Cơm tăng ca | AL30: Cơm Tăng Ca | AM30: =COUNTA(I30:AL30) -> 3
A31: Active | B31: 26002 | C31: Trần Hoài Yến Nhi | D31: HHVCV | F31: Dầu Giây | AK31: Cơm tăng ca | AM31: =COUNTA(I31:AL31) -> 1
A32: Active | C32: Nguyễn Minh Phụng | D32: HHVCV | F32: Dầu Giây | AK32: Cơm tăng ca | AM32: =COUNTA(I32:AL32) -> 1
A33: Active | C33: Phạm Thị Thuỳ Tiên | D33: HHVCV | F33: Dầu Giây | AJ33: Cơm tăng ca | AK33: Cơm tăng ca | AM33: =COUNTA(I33:AL33) -> 2
A34: Active | C34: Võ Minh Đạt | D34: HHVCV | F34: Dầu Giây | AE34: Cơm tăng ca | AM34: =COUNTA(I34:AL34) -> 1
A35: Active | B35: VCV0320 | C35: Đõ Lệ Ngọc | D35: PMC - WH | E35: PMC - WH | F35: Dầu Giây | AJ35: Cơm tăng ca | AM35: =COUNTA(I35:AL35) -> 1
A36: Active | B36: VCV0788 | C36: Diệu Ngọc | D36: PMC - WH | E36: PMC - WH | F36: Dầu Giây | AJ36: Cơm tăng ca | AM36: =COUNTA(I36:AL36) -> 1
A37: Active | B37: VCV0719 | C37: Trịnh Xuân Trường | D37: PMC - WH | E37: PMC - WH | F37: Dầu Giây | AJ37: Cơm tăng ca | AM37: =COUNTA(I37:AL37) -> 1
A38: Active | B38: VCV0750 | C38: Huỳnh Khánh Duy | D38: PMC - WH | E38: PMC - WH | F38: Dầu Giây | AJ38: Cơm tăng ca | AM38: =COUNTA(I38:AL38) -> 1
A39: Active | B39: VCV0623 | C39: Phạm Văn Tuấn | D39: PMC - WH | E39: PMC - WH | F39: Dầu Giây | AJ39: Cơm tăng ca | AM39: =COUNTA(I39:AL39) -> 1
A40: Active | B40: VCV0787 | C40: Nguyễn Phúc Ân | D40: PMC - WH | E40: PMC - WH | F40: Dầu Giây | AM40: =COUNTA(I40:AL40) -> 0
A41: Active | B41: VCV0756 | C41: Lường Chắn Hoa | D41: PMC - WH | E41: PMC - WH | F41: Dầu Giây | AJ41: Cơm tăng ca | AM41: =COUNTA(I41:AL41) -> 1
A42: Active | C42: Trần Minh Hiếu | D42: PMC - WH | E42: PMC - WH | F42: Dầu Giây | AJ42: Cơm tăng ca | AM42: =COUNTA(I42:AL42) -> 1
A43: Active | B43: VCV0444 | C43: Lê Doãn Hội | D43: PMC - WH | E43: PMC - WH | F43: Dầu Giây | AM43: =COUNTA(I43:AL43) -> 0
...

Sheet Payment
A1: Meal Consumption & Cost Summary on May 2026
A3: 1. Meal Summary by Date
A5: Date | B5: Expat Meals Cơm chuyên gia Trung Quốc | C5: Expat Meals - Overtime Cơm chuyên gia Trung Quốc - Tăng ca | D5: Shift 1+ Nomal Meals Cơm ca 1 + Cơm hành chính | E5: Shift 2 Meals Cơm ca 2 | F5: Overtime Meals Cơm tăng ca | G5: Total Meals per day Tổng phần ăn
A6: 46266 | B6: ='VP SÁNG '!I9 -> 25 | C6: 0 | D6: ='VP SÁNG '!I10 -> 336 | E6: ='CHIỀU '!I10 -> 3 | F6: ='CHIỀU '!I11 -> 13 | G6: =SUM(B6:F6) -> 377
A7: 46267 | B7: ='VP SÁNG '!J9 -> 0 | C7: 0 | D7: ='VP SÁNG '!J10 -> 0 | E7: ='CHIỀU '!J10 -> 0 | F7: ='CHIỀU '!J11 -> 0 | G7: =SUM(B7:F7) -> 0
A8: 46268 | B8: ='VP SÁNG '!K9 -> 0 | C8: 0 | D8: ='VP SÁNG '!K10 -> 0 | E8: ='CHIỀU '!K10 -> 0 | F8: ='CHIỀU '!K11 -> 0 | G8: =SUM(B8:F8) -> 0
A9: 46269 | B9: ='VP SÁNG '!L9 -> 25 | C9: 0 | D9: ='VP SÁNG '!L10 -> 333 | E9: ='CHIỀU '!L10 -> 3 | F9: ='CHIỀU '!L11 -> 127 | G9: =SUM(B9:F9) -> 488
A10: 46270 | B10: ='VP SÁNG '!M9 -> 24 | C10: 0 | D10: ='VP SÁNG '!M10 -> 339 | E10: ='CHIỀU '!M10 -> 3 | F10: ='CHIỀU '!M11 -> 15 | G10: =SUM(B10:F10) -> 381
A11: 46271 | B11: ='VP SÁNG '!N9 -> 5 | C11: 0 | D11: ='VP SÁNG '!N10 -> 67 | E11: ='CHIỀU '!N10 -> 0 | F11: ='CHIỀU '!N11 -> 0 | G11: =SUM(B11:F11) -> 72
A12: 46272 | B12: ='VP SÁNG '!O9 -> 25 | C12: 0 | D12: ='VP SÁNG '!O10 -> 345 | E12: ='CHIỀU '!O10 -> 3 | F12: ='CHIỀU '!O11 -> 121 | G12: =SUM(B12:F12) -> 494
A13: 46273 | B13: ='VP SÁNG '!P9 -> 25 | C13: 0 | D13: ='VP SÁNG '!P10 -> 304 | E13: ='CHIỀU '!P10 -> 10 | F13: ='CHIỀU '!P11 -> 123 | G13: =SUM(B13:F13) -> 462
A14: 46274 | B14: ='VP SÁNG '!Q9 -> 23 | C14: 0 | D14: ='VP SÁNG '!Q10 -> 306 | E14: ='CHIỀU '!Q10 -> 11 | F14: ='CHIỀU '!Q11 -> 131 | G14: =SUM(B14:F14) -> 471
A15: 46275 | B15: ='VP SÁNG '!R9 -> 26 | C15: 0 | D15: ='VP SÁNG '!R10 -> 316 | E15: ='CHIỀU '!R10 -> 10 | F15: ='CHIỀU '!R11 -> 103 | G15: =SUM(B15:F15) -> 455
A16: 46276 | B16: ='VP SÁNG '!S9 -> 25 | C16: 0 | D16: ='VP SÁNG '!S10 -> 290 | E16: ='CHIỀU '!S10 -> 7 | F16: ='CHIỀU '!S11 -> 108 | G16: =SUM(B16:F16) -> 430
A17: 46277 | B17: ='VP SÁNG '!T9 -> 23 | C17: 0 | D17: ='VP SÁNG '!T10 -> 288 | E17: ='CHIỀU '!T10 -> 11 | F17: ='CHIỀU '!T11 -> 17 | G17: =SUM(B17:F17) -> 339
A18: 46278 | B18: ='VP SÁNG '!U9 -> 0 | C18: 0 | D18: ='VP SÁNG '!U10 -> 0 | E18: ='CHIỀU '!U10 -> 0 | F18: ='CHIỀU '!U11 -> 0 | G18: =SUM(B18:F18) -> 0
A19: 46279 | B19: ='VP SÁNG '!V9 -> 27 | C19: 0 | D19: ='VP SÁNG '!V10 -> 340 | E19: ='CHIỀU '!V10 -> 3 | F19: ='CHIỀU '!V11 -> 116 | G19: =SUM(B19:F19) -> 486
A20: 46280 | B20: ='VP SÁNG '!W9 -> 27 | C20: 0 | D20: ='VP SÁNG '!W10 -> 343 | E20: ='CHIỀU '!W10 -> 11 | F20: ='CHIỀU '!W11 -> 215 | G20: =SUM(B20:F20) -> 596
A21: 46281 | B21: ='VP SÁNG '!X9 -> 26 | C21: 0 | D21: ='VP SÁNG '!X10 -> 345 | E21: ='CHIỀU '!X10 -> 9 | F21: ='CHIỀU '!X11 -> 221 | G21: =SUM(B21:F21) -> 601
A22: 46282 | B22: ='VP SÁNG '!Y9 -> 25 | C22: 0 | D22: ='VP SÁNG '!Y10 -> 350 | E22: ='CHIỀU '!Y10 -> 9 | F22: ='CHIỀU '!Y11 -> 229 | G22: =SUM(B22:F22) -> 613
A23: 46283 | B23: ='VP SÁNG '!Z9 -> 24 | C23: 0 | D23: ='VP SÁNG '!Z10 -> 353 | E23: ='CHIỀU '!Z10 -> 3 | F23: ='CHIỀU '!Z11 -> 134 | G23: =SUM(B23:F23) -> 514
A24: 46284 | B24: ='VP SÁNG '!AA9 -> 22 | C24: 0 | D24: ='VP SÁNG '!AA10 -> 341 | E24: ='CHIỀU '!AA10 -> 3 | F24: ='CHIỀU '!AA11 -> 27 | G24: =SUM(B24:F24) -> 393
A25: 46285 | B25: ='VP SÁNG '!AB9 -> 6 | C25: 0 | D25: ='VP SÁNG '!AB10 -> 67 | E25: ='CHIỀU '!AB10 -> 0 | F25: ='CHIỀU '!AB11 -> 0 | G25: =SUM(B25:F25) -> 73
A26: 46286 | B26: ='VP SÁNG '!AC9 -> 25 | C26: 0 | D26: ='VP SÁNG '!AC10 -> 336 | E26: ='CHIỀU '!AC10 -> 10 | F26: ='CHIỀU '!AC11 -> 209 | G26: =SUM(B26:F26) -> 580
A27: 46287 | B27: ='VP SÁNG '!AD9+HHVCV!AD7 -> 38 | C27: ='HHVCV - Tăng ca'!AD10 -> 10 | D27: ='VP SÁNG '!AD10+HHVCV!AD8 -> 410 | E27: ='CHIỀU '!AD10 -> 10 | F27: ='CHIỀU '!AD11+'HHVCV - Tăng ca'!AD11 -> 235 | G27: =SUM(B27:F27) -> 703
A28: 46288 | B28: ='VP SÁNG '!AE9+HHVCV!AE7 -> 39 | C28: ='HHVCV - Tăng ca'!AE10 -> 10 | D28: ='VP SÁNG '!AE10+HHVCV!AE8 -> 371 | E28: ='CHIỀU '!AE10 -> 10 | F28: ='CHIỀU '!AE11+'HHVCV - Tăng ca'!AE11 -> 244 | G28: =SUM(B28:F28) -> 674
A29: 46289 | B29: ='VP SÁNG '!AF9+HHVCV!AF7 -> 39 | C29: ='HHVCV - Tăng ca'!AF10 -> 10 | D29: ='VP SÁNG '!AF10+HHVCV!AF8 -> 370 | E29: ='CHIỀU '!AF10 -> 9 | F29: ='CHIỀU '!AF11+'HHVCV - Tăng ca'!AF11 -> 229 | G29: =SUM(B29:F29) -> 657
A30: 46290 | B30: ='VP SÁNG '!AG9+HHVCV!AG7 -> 38 | C30: ='HHVCV - Tăng ca'!AG10 -> 0 | D30: ='VP SÁNG '!AG10+HHVCV!AG8 -> 378 | E30: ='CHIỀU '!AG10 -> 3 | F30: ='CHIỀU '!AG11+'HHVCV - Tăng ca'!AG11 -> 85 | G30: =SUM(B30:F30) -> 504
A31: 46291 | B31: ='VP SÁNG '!AH9+HHVCV!AH7 -> 37 | C31: ='HHVCV - Tăng ca'!AH10 -> 10 | D31: ='VP SÁNG '!AH10+HHVCV!AH8 -> 362 | E31: ='CHIỀU '!AH10 -> 10 | F31: ='CHIỀU '!AH11+'HHVCV - Tăng ca'!AH11 -> 17 | G31: =SUM(B31:F31) -> 436
